Workbook

Sheet 使用方法&新聞
A1: 此表單使用方法 | C1: 我會從紅綠篩選頁面內挑自己有興趣的股票進模擬盤跑 而實際真實買賣會公告在"買賣通知line群"並填寫進"持股"頁面 | J1: 資料去這邊抓
C2: 初步篩選出標的後 還需要去查各股相關新聞 看是否利空利多 常有突然被檢調 或是倒貨 欠賬的公司 然後剔除 | J2: 每月期貨結算日 (每月第三個禮拜三) | K2: https://www.taifex.com.tw/file/taifex/CHINESE/4/2026Calendar.pdf
C3: 模擬操作會同步貼到 "模擬盤"並每日更新<我寫入只代表我關注 不代表我一定買進!!> | J3: 外資未平倉口數 | K3: https://stock.wearn.com/taifexphoto.asp
C4: 請其他使用者自行開立自己的google sheet 自己記錄自己的操作!!!! 不要寫在這邊讓我看到!! | J4: 外資未平倉口數2 | K4: https://www.taifex.com.tw/cht/3/futContractsDate
J5: 外資買賣超排行 | K5: https://tw.stock.yahoo.com/rank/foreign-investor-buy
A6: 規律跌注意: | B6: 1.每月月初123 (遇假日提前發生) <外資結算> | E6: 3.每月期貨結算請看期貨行事曆 | G6: 5. 每500點階段 | J6: 除權息資訊 | K6: https://concords.moneydj.com/z/ze/zeb/zeb.djhtm
B7: 2.每月第一個星期5 非農 | E7: 4.連假 | G7: 6. 每月10日財報公布 | J7: 除權息資訊2(拉到下方) | K7: https://mops.twse.com.tw/mops/#/web/home
B8: 7.每年過農曆年會提前休市 需要注意去查實際休市日 | J8: 上市櫃注意股查詢 (當天) | K8: https://www.twse.com.tw/zh/announcement/notice.html
B9: 放假 | C9: 漲 | D9: 跌 | E9: 消息日 不確定 | F9: 上格為事前猜 中格為實際 下格為操作 最下格為失準原因or世界情勢 | J9: 上市處置股查詢 | K9: https://www.twse.com.tw/zh/announcement/punish.html
A10: 個人行事曆 | B10: 日 | C10: 一 | D10: 二 | E10: 三 | F10: 四 | G10: 五 | H10: 六 | I10: 每季檢查MSCI | J10: 上櫃處置股查詢 | K10: https://www.tpex.org.tw/zh-tw/announce/market/disposal.html
A11: 46113 | B11: 29 | C11: 30/外資結算前 | D11: 31/外資結算前 | E11: 1/外資結算 | F11: 2/連假前 | G11: 3/清明節 非農 | H11: 4 | I11: 每年2/5/8/11月 | J11: 美國非農就業數據 (每月第一個星期五更新) | K11: https://tradingeconomics.com/united-states/non-farm-payrolls
C12: 市跌 772/1047 櫃跌 603/825 空單: -37282 | D12: 市跌 890/1047 櫃跌 699/825 空單: -37214 | E12: 市跌 100/1047 櫃跌 110/825 空單: -31373 | F12: 市跌 566/1047 櫃跌 788/825 空單: -34855 | J12: 上市櫃公司當日重大訊息 | K12: https://mops.twse.com.tw/mops/#/web/t05sr01_1
J13: 三大法人買賣超統計 | K13: https://www.twse.com.tw/zh/trading/foreign/bfi82u.html
E14: 伊朗發布停戰 | J14: 上市股漲跌狀況 | K14: https://www.twse.com.tw/zh/trading/historical/mi-index.html
B15: 5 | C15: 6/清明節 | D15: 7 | E15: 8 | F15: 9 | G15: 10/財報 | H15: 11 | J15: 上櫃股漲跌狀況 | K15: https://www.tpex.org.tw/zh-tw/mainboard/trading/historical/decline/day.html
D16: 市跌 468/1047 櫃跌 364/825 空單: -31350 | E16: 市跌 154/1047 櫃跌 172/825 空單: -32478 | F16: 市跌 566/1047 櫃跌 461/825 空單: -33399 | G16: 市跌 452/1047 櫃跌 343/825 空單: -34403 | J16: 查詢上市上櫃月營收 (每月10號前更新) | K16: https://mops.twse.com.tw/mops/#/web/t21sc04_ifrs
D17: 買回 | G17: 賣出 | J17: 查詢個股財務報表(財報狗) | K17: https://statementdog.com/
G18: 停戰談判 | J18: 查詢財務報表(win投資) | K18: https://winvest.tw/Stock/Symbol/Comment/1101
B19: 12 | C19: 13 | D19: 14 | E19: 15/期貨結算 | F19: 16 期貨回補 | G19: 17 | H19: 18 | J19: 查詢本益比(上市) | K19: https://www.twse.com.tw/zh/trading/historical/bwibbu.html
C20: 市跌 405/1047 櫃跌 384/825 空單: -35996 | D20: 市跌 331/1047 櫃跌 386/825 空單: -36664 | E20: 市跌 389/1047 櫃跌 385/825 空單: -36783 | F20: 市跌 389/1047 櫃跌 308/825 空單: -39683 | G20: 市跌 499/1047 櫃跌 376/825 空單: -41151 | J20: 查詢本益比(上櫃) | K20: https://www.tpex.org.tw/zh-tw/mainboard/trading/info/stock-pe.html
E21: 買回 | F21: 更改漲跌預估 | G21: 更改漲跌預估 | J21: 群益證卷即時消息(點選重要) | K21: https://www.capitalfutures.com.tw/zh-tw/financial/breakingnews?date=2026-04-01&important=0
C22: 停戰談判 | D22: 停戰談判 | J22: 每日融資融卷增減(上市) | K22: https://accessibility.twse.com.tw/zh/trading/margn/MI_MARGN-margin-dec30.html
B23: 19 | C23: 20 | D23: 21 | E23: 22 | F23: 23 | G23: 24 | H23: 25 | J23: 每日融資融卷增減(上櫃) | K23: https://www.tpex.org.tw/zh-tw/mainboard/trading/margin-trading/rank/day.html
C24: 市跌 532/1047 櫃跌 415/825 空單: -42618 | D24: 市跌 499/1047 櫃跌 364/825 空單: -41295 | J24: 個股每日融資融卷查詢 | K24: https://concords.moneydj.com/z/zc/zcn/zcn.djhtm?a=2330&b=3
C25: 更改漲跌預估 | D25: 更改漲跌預估 | E25: 更改漲跌預估 | J25: Chengwaye 台股觀測站 | K25: https://chengwaye.com/
B27: 26 | C27: 27 | D27: 28 | E27: 29 | F27: 30/月底結算 | G27: 1 | H27: 2
J28: 政府連假行事曆
B31: 3 | C31: 4 | D31: 5 | E31: 6 | F31: 7 | G31: 8 | H31: 9
A36: 注意事項:
B37: 1. 期貨周規律: | C37: 依據2025/11~2026/1的歷史紀錄 期貨周漲跌起伏太劇烈
C38: 最安全的方法為上禮拜五賣出 禮拜五才回補 因為通常下禮拜一都是漲
C39: 不要在期貨周內買入賺最大收益 沒辦法100%賺 至少100%不要賠
B40: 2.假期中間有一個工作日的狀況: (參考2025/12)
C41: 依據2025/12的歷史紀錄 當應該是連假時 但是中間安插了一個工作日
C42: 連假前仍然會暴跌 但是"當個工作日"會回補
C43: 正確操作是連假前的第三天要賣出 然後連假前最後一天買入 然後等"當個工作日"回補
B44: 3. 基於空單口數決定進出場日子
C45: 經由AI分析 當低於-25000時 可進場 當逼近-35000時 必須出場
A46: 優先題材(綠): | B46: 軍工 | C46: 生技醫療 | D46: PCB | E46: BBU | F46: 航太 | G46: 資訊服務 | H46: 安全監控 | I46: 機器人
A47: 46054 | B47: DIMM/DRAM | C47: 航運 | D47: 被動元件 | E47: 矽 | F47: 特化 | G47: 封測 | H47: 低軌衛星 | I47: 光通訊
...

Sheet 基本觀念
A1: 股市循環觀察
A2: 每月循環 | B2: 每月開頭的1 2 3 交易日 依據歷史 當日都會暴跌(跟外資匯款限制有關) <代表每月月初可以低價買入 然後下月第一周賣出>
B3: 每年的9 月 是股災月 依據歷史 整體都是跌 <代表八月底要賣光 因為市場共識 導致散戶亂賣 9月大跌可找低點進場>
B4: 每個關鍵點位(大盤每500點) 達到目標點後 隔天都會大暴跌(外資殺盤) 請在此時前賣出 然後看情況最低點(第三天)買回
B5: 每個月第三周的星期三 要注意期貨結算日 當周會有超大震盪 建議第二周周五賣光獲利 <依據歷史紀錄 第三周會出現三種狀況>
C6: 1.結算日爆殺 此時結算日可買進
C7: 2.結算日前爆殺 可以買進 結算日會暴漲
C8: 3.結算日前平盤 結算日暴漲 則後續幾天 會爆殺>
A9: 基本觀念
A10: 外資未平倉口數增加或減少 該怎麼理解?
B11: 1.如果股市當天大跌 且 當天外資未平倉口數下降 可視為跌深反彈的訊號
A12: 什麼是紅綠買賣壓? 代表什麼意思 我應該如何使用?
B13: 先說結論: | C13: 綠比率(賣壓) > 紅比率(買壓) 代表此"瞬間"股票還會往上漲 反之 紅比率>綠比率 代表此"瞬間" 股票還會往下跌 直到比率平衡50:50保持穩定
B14: 原理舉例: | C14: 假如我們只會看到如下兩行 不是五行
C15: 10 X:O 20
C16: 15 XX:OO 20
C17: 目前股價在X:O 這行
C18: 總賣壓比較會是 10+15 : 20+20
C19: 當我們價錢推進 從X:O 跑到XX:OO
C20: 第一行消失 第一行的賣 20 被買光了對吧? 所以此行價位會從賣壓變買壓 此時變成 ?? O:OO 20
C21: 但是在O從賣變買的瞬間 是不是沒有人掛單 所以他是變成 0 O:OO 20 因為那個瞬間 賣被買光了 但買的掛單還沒人開始下
C22: 是不是 就變成突然賣壓高 所以才會顯示 綠色賣壓多於買壓 但是以股價來看 他卻是漲上去
C23: 當這個瞬間一直發生(大戶瘋狂買) 就變成連續性 然後股價就會一直往上衝 所以賣壓才會看起來一直維持比買壓高
C24: 反之 賣壓(紅)>買壓(綠) 也是同樣道理
C25: 此現象直到 比率平衡 此現象才會消失(因為沒人要往上買 或是往下賣了)
C26: 所以當天看到想要的股票時
... C28: 如果看到他跌 紅綠條 紅比較長 你可以預期他還會繼續跌 所以你可以等到紅綠條平衡再買
A29: 怎麼看待美國非農就業數據?
B30: 此為美國經濟基礎 只要非農就業高於預期 代表美國經濟好轉 會連帶影響台股"科技業"也走紅
A31: 關於除權息該怎麼看待:
B32: 就是很現實的左手換右手 幫你被動賣出又買進 唯一幫你省的只有少了1%手續費 對你個人來說 實際上根本沒賺沒賠
B33: 依據統計 大部分股票 根本不可能短時間內填息成功 而且懂這邏輯的大戶 還會在除息前的高點 直接大賣停利 導致股價跌更深
B34: 所以手持股票如果近期要除權除息 而且是在 "獲利中"的股票 強烈建議在該日期前賣出 雖然也有少數會秒填息 但是畢竟是"少數"
B35: 除非你手上現在這檔股票已經在賠錢了 那就放著吧 可以賭看看跌深反彈
A36: 如何看待現金增資
B37: 所有"高檔價位"股票 搞現金增資 增完股價就會連吃好幾隻跌停 有看到要增資的股票 要快點出清 原因在於 現金增資公司開的價位一定少於目前股票價位 會有一大波賣出賺價差
A38: 關於每大盤每漲500點 當天或隔天就會大崩跌的 階段崩跌 的狀況 (大盤盤面很好看的還是顯示大漲 但是實際上 大多股票都是綠 所以不能只單看大盤顯示數據
E39: 平日上市跌數約300~400 | F39: https://www.twse.com.tw/zh/trading/historical/mi-index.html
E40: 平日上櫃跌數約250~300 | F40: https://www.tpex.org.tw/zh-tw/mainboard/trading/historical/decline/day.html
B41: 日期 | C41: 大盤突破狀況 | D41: 實際狀況 | E41: 資料佐證
...

Sheet STOCKS
A1: ID | B1: Name | C1: Type | D1: 收盤價 | E1: 價差 | F1: 漲幅(%) | G1: 五日+- | H1: 五日漲幅(%) | I1: 漲停歷史 | J1: 交易量(張) | K1: 周轉率(%) | L1: MA5 | M1: MA10 | N1: MA20 | O1: 外資(張) | P1: 外資五日+- | Q1: 投信(張) | R1: 自營(張) | S1: 當沖(張) | T1: 當沖(%) | U1: Date | V1: News | W1: ExDate
A2: 2812 | B2: 台中銀 | C2: 金融保險業 | D2: 20.5 | E2: -0.05 | F2: -0.24 | G2: '----- | H2: -1.2 | I2: 0 | J2: 13171 | K2: 0.22 | L2: 20.62 | M2: 20.81 | N2: 20.69 | O2: -5542 | P2: '----- | Q2: 5 | R2: 53 | S2: 1216 | T2: 9.23 | U2: 46132
A3: 1708 | B3: 東鹼 | C3: 化學工業 | D3: 39.3 | E3: -0.05 | F3: -0.13 | G3: '----- | H3: -6.12 | I3: 0 | J3: 2652 | K3: 1.07 | L3: 40.1 | M3: 40.36 | N3: 41.49 | O3: 241 | P3: '-+-++ | Q3: -76 | R3: -4 | S3: 886 | T3: 33.41 | U3: 46132
A4: 6875 | B4: 國邑* | C4: 生技醫療業 | D4: 36 | E4: -0.85 | F4: -2.31 | G4: '-++-- | H4: -3.1 | I4: 0 | J4: 262 | K4: 0.2 | L4: 36.92 | M4: 37.33 | N4: 38.17 | O4: 19 | P4: '+++-+ | Q4: 0 | R4: 0 | S4: 0 | T4: 0 | U4: 46132
A5: 1340 | B5: 勝悅-KY | C5: 塑膠工業 | D5: 6.34 | E5: -0.07 | F5: -1.09 | G5: '+---- | H5: -1.55 | I5: 0 | J5: 232 | K5: 0.15 | L5: 6.43 | M5: 6.51 | N5: 6.64 | O5: 15 | P5: '+---+ | Q5: 0 | R5: 0 | S5: 16 | T5: 6.9 | U5: 46132
A6: 6996 | B6: 力領科技 | C6: 半導體業 | D6: 186 | E6: 1 | F6: 0.54 | G6: '++-++ | H6: 8.33 | I6: 0 | J6: 287 | K6: 0.68 | L6: 183.9 | M6: 176.5 | N6: 171.82 | O6: -23 | P6: '++-+- | Q6: 0 | R6: 0 | S6: 47 | T6: 16.38 | U6: 46132 | W6: 46135
A7: 4588 | B7: 玖鼎電力 | C7: 其他電子業 | D7: 60.3 | E7: 0.1 | F7: 0.17 | G7: '--+-+ | H7: -2.43 | I7: 0 | J7: 124 | K7: 0.29 | L7: 60.62 | M7: 59.6 | N7: 59.1 | O7: 34 | P7: '-++++ | Q7: 0 | R7: 3 | S7: 16 | T7: 12.9 | U7: 46132
A8: 2247 | B8: 汎德永業 | C8: 汽車工業 | D8: 230.5 | E8: -4 | F8: -1.71 | G8: '-+--- | H8: -3.59 | I8: 0 | J8: 163 | K8: 0.2 | L8: 234.4 | M8: 236.7 | N8: 236.35 | O8: -40 | P8: '-++-- | Q8: -20 | R8: 0 | S8: 5 | T8: 3.07 | U8: 46132
A9: 8932 | B9: 智通* | C9: 其他業 | D9: 98.8 | E9: 8.9 | F9: 9.9 | G9: '+--++ | H9: 19.82 | I9: 1 | J9: 4279 | K9: 1.2 | L9: 90.06 | M9: 86.05 | N9: 83.99 | O9: -445 | P9: '---+- | Q9: 0 | R9: 78 | S9: 1104 | T9: 25.8 | U9: 46132
A10: 6887 | B10: 寶綠特-KY | C10: 綠能環保 | D10: 40.3 | E10: -1.75 | F10: -4.16 | G10: '++--- | H10: -3.2 | I10: 1 | J10: 77 | K10: 0.1 | L10: 41.83 | M10: 42.52 | N10: 43.27 | O10: 16 | P10: '+++++ | Q10: 0 | R10: 1 | S10: 12 | T10: 15.58 | U10: 46132
A11: 6680 | B11: 鑫創電子 | C11: 電腦及週邊設備業 | D11: 55.7 | E11: 0.5 | F11: 0.91 | G11: '+---+ | H11: 1.5 | I11: 0 | J11: 14 | K11: 0.06 | L11: 55.82 | M11: 55.63 | N11: 56.23 | O11: 2 | P11: '-+--+ | Q11: 0 | R11: 0 | S11: 5 | T11: 35.71 | U11: 46132
A12: 6761 | B12: 穩得 | C12: 電子零組件業 | D12: 194.5 | E12: -1 | F12: -0.51 | G12: '---+- | H12: -5.6 | I12: 3 | J12: 1033 | K12: 2.96 | L12: 194.9 | M12: 188 | N12: 177.25 | O12: -32 | P12: '+-++- | Q12: 0 | R12: 19 | S12: 431 | T12: 41.72 | U12: 46132
A13: 1532 | B13: 勤美 | C13: 電機機械 | D13: 21.65 | E13: -0.15 | F13: -0.69 | G13: '+-+-- | H13: -1.11 | I13: 0 | J13: 728 | K13: 0.17 | L13: 21.87 | M13: 21.93 | N13: 21.96 | O13: -65 | P13: '+-+-- | Q13: -36 | R13: -15 | S13: 38 | T13: 5.22 | U13: 46132
A14: 2480 | B14: 敦陽科 | C14: 資訊服務業 | D14: 140 | E14: -0.5 | F14: -0.36 | G14: '+-++- | H14: 1.08 | I14: 0 | J14: 416 | K14: 0.39 | L14: 139.7 | M14: 139.75 | N14: 139.88 | O14: -37 | P14: '--++- | Q14: -3 | R14: 0 | S14: 51 | T14: 12.26 | U14: 46132
A15: 2367 | B15: 燿華 | C15: 電子零組件業 | D15: 65.6 | E15: -2.9 | F15: -4.23 | G15: '-+--- | H15: -11.85 | I15: 1 | J15: 61759 | K15: 8.74 | L15: 69.72 | M15: 72.11 | N15: 72.91 | O15: 6083 | P15: '-+--+ | Q15: -431 | R15: -808 | S15: 24374 | T15: 39.47 | U15: 46132
A16: 4557 | B16: 永新-KY | C16: 汽車工業 | D16: 52.7 | E16: -0.9 | F16: -1.68 | G16: '-++-- | H16: -2.37 | I16: 0 | J16: 125 | K16: 0.26 | L16: 53.64 | M16: 54.74 | N16: 56.71 | O16: 41 | P16: '+-+-+ | Q16: 0 | R16: 0 | S16: 15 | T16: 12 | U16: 46132
A17: 3231 | B17: 緯創 | C17: 電腦及週邊設備業 | D17: 140.5 | E17: 4 | F17: 2.93 | G17: '+-+++ | H17: 4.48 | I17: 0 | J17: 79145 | K17: 2.49 | L17: 136.1 | M17: 133.7 | N17: 130.18 | O17: 31159 | P17: '+--++ | Q17: 827 | R17: 1095 | S17: 22772 | T17: 28.77 | U17: 46132 | V17: 代⼦公司Wiwynn Technology Corporation(WYMUS)公告進行建築物改良
A18: 3527 | B18: 聚積 | C18: 半導體業 | D18: 58.7 | E18: -1.2 | F18: -2 | G18: '++++- | H18: 10.16 | I18: 0 | J18: 207 | K18: 0.47 | L18: 57.8 | M18: 55.48 | N18: 53.9 | O18: -56 | P18: '++++- | Q18: 0 | R18: 0 | S18: 27 | T18: 13.04 | U18: 46132
A19: 6592 | B19: 和潤企業 | C19: 其他業 | D19: 64.1 | E19: -0.4 | F19: -0.62 | G19: '+++-- | H19: 2.08 | I19: 0 | J19: 808 | K19: 0.13 | L19: 64.36 | M19: 63.5 | N19: 63.54 | O19: 255 | P19: '+++++ | Q19: 0 | R19: -94 | S19: 181 | T19: 22.4 | U19: 46132
A20: 2501 | B20: 國建 | C20: 建材營造業 | D20: 24.8 | E20: 0.35 | F20: 1.43 | G20: '++--+ | H20: 3.13 | I20: 0 | J20: 2772 | K20: 0.24 | L20: 24.69 | M20: 24.01 | N20: 23.67 | O20: 159 | P20: '+++++ | Q20: 4 | R20: 572 | S20: 611 | T20: 22.04 | U20: 46132
A21: 3093 | B21: 港建* | C21: 其他電子業 | D21: 73.5 | E21: 0.5 | F21: 0.68 | G21: '++--+ | H21: 17.02 | I21: 5 | J21: 5376 | K21: 3.7 | L21: 72.82 | M21: 66.42 | N21: 55.69 | O21: -528 | P21: '-+--- | Q21: 0 | R21: 0 | S21: 2316 | T21: 43.08 | U21: 46132
A22: 5403 | B22: 中菲 | C22: 資訊服務業 | D22: 93 | E22: -1.4 | F22: -1.48 | G22: '-++-- | H22: -2.12 | I22: 0 | J22: 127 | K22: 0.16 | L22: 93.54 | M22: 95.94 | N22: 99.5 | O22: -23 | P22: '++++- | Q22: 0 | R22: 3 | S22: 4 | T22: 3.15 | U22: 46132
A23: 6753 | B23: 龍德造船 | C23: 航運業 | D23: 144 | E23: 5.5 | F23: 3.97 | G23: '+++-+ | H23: 14.62 | I23: 0 | J23: 2714 | K23: 2.31 | L23: 138.6 | M23: 132.75 | N23: 130.88 | O23: 343 | P23: '+++++ | Q23: 0 | R23: 191 | S23: 1149 | T23: 42.34 | U23: 46132
A24: 6928 | B24: 攸泰科技 | C24: 電腦及週邊設備業 | D24: 48.7 | E24: -0.1 | F24: -0.2 | G24: '++-+- | H24: 6.56 | I24: 0 | J24: 144 | K24: 0.17 | L24: 48.21 | M24: 47.02 | N24: 46.71 | O24: -27 | P24: '+++-- | Q24: 0 | R24: 0 | S24: 35 | T24: 24.31 | U24: 46132
A25: 3576 | B25: 聯合再生 | C25: 光電業 | D25: 17.2 | E25: -1.1 | F25: -6.01 | G25: '-++-- | H25: 2.2 | I25: 4 | J25: 35648 | K25: 2.19 | L25: 17.27 | M25: 18.4 | N25: 20.27 | O25: 6525 | P25: '+++-+ | Q25: 0 | R25: -6 | S25: 0 | T25: 0 | U25: 46132
A26: 2323 | B26: 中環 | C26: 光電業 | D26: 10.75 | E26: 0 | F26: 0 | G26: '+-+-- | H26: 0.02 | I26: 1 | J26: 4122 | K26: 0.38 | L26: 10.83 | M26: 10.86 | N26: 11.21 | O26: 287 | P26: '+-+-+ | Q26: 0 | R26: -135 | S26: 1019 | T26: 24.72 | U26: 46132 | V26: 公告本公司取得有價證券
A27: 2301 | B27: 光寶科 | C27: 電腦及週邊設備業 | D27: 165 | E27: 3 | F27: 1.85 | G27: '+++++ | H27: 7.29 | I27: 1 | J27: 30332 | K27: 1.31 | L27: 160.9 | M27: 157.35 | N27: 154.32 | O27: 7914 | P27: '+++++ | Q27: -1339 | R27: -51 | S27: 9939 | T27: 32.77 | U27: 46132 | V27: 光寶科技115年第一季法人說明會
A28: 2867 | B28: 三商壽 | C28: 金融保險業 | D28: 7.88 | E28: 0.01 | F28: 0.13 | G28: '++--+ | H28: 2.34 | I28: 0 | J28: 12565 | K28: 0.21 | L28: 7.89 | M28: 7.82 | N28: 7.73 | O28: 7056 | P28: '+++++ | Q28: 0 | R28: -1405 | S28: 2023 | T28: 16.1 | U28: 46132
A29: 5289 | B29: 宜鼎 | C29: 電腦及週邊設備業 | D29: 1020 | E29: 15 | F29: 1.49 | G29: '+---+ | H29: -10.13 | I29: 2 | J29: 3108 | K29: 3.23 | L29: 1086 | M29: 1087.8 | N29: 1035.65 | O29: 70 | P29: '----+ | Q29: -75 | R29: 23 | S29: 1417 | T29: 45.59 | U29: 46132
A30: 2006 | B30: 東和鋼鐵 | C30: 鋼鐵工業 | D30: 70.1 | E30: -1.7 | F30: -2.37 | G30: '--++- | H30: -1.51 | I30: 0 | J30: 3004 | K30: 0.41 | L30: 70.76 | M30: 70.79 | N30: 70.58 | O30: -526 | P30: '--++- | Q30: 60 | R30: -54 | S30: 725 | T30: 24.13 | U30: 46132 | V30: 公告本公司115年第1季合併財務報告董事會預計召開 日期為115年04月28日
A31: 6491 | B31: 晶碩 | C31: 生技醫療業 | D31: 288 | E31: -5.5 | F31: -1.87 | G31: '+++-- | H31: 0.73 | I31: 0 | J31: 321 | K31: 0.41 | L31: 291.2 | M31: 290.55 | N31: 285.8 | O31: -136 | P31: '++++- | Q31: -1 | R31: -1 | S31: 39 | T31: 12.15 | U31: 46132
A32: 6431 | B32: 光麗-KY | C32: 生技醫療業 | D32: 21.3 | E32: 0 | F32: 0 | G32: '---+- | H32: -3.17 | I32: 2 | J32: 82 | K32: 0.08 | L32: 21.38 | M32: 21.87 | N32: 22.13 | O32: -15 | P32: '+-++- | Q32: 0 | R32: -1 | S32: 0 | T32: 0 | U32: 46132
A33: 1467 | B33: 南緯 | C33: 紡織纖維 | D33: 7 | E33: 0 | F33: 0 | G33: '++--- | H33: -0.71 | I33: 0 | J33: 155 | K33: 0.07 | L33: 7.03 | M33: 7.04 | N33: 7.05 | O33: 18 | P33: '++--+ | Q33: 0 | R33: 0 | S33: 17 | T33: 10.97 | U33: 46132
A34: 7788 | B34: 松川精密 | C34: 電子零組件業 | D34: 167 | E34: 4 | F34: 2.45 | G34: '++-++ | H34: 14.17 | I34: 1 | J34: 817 | K34: 1.02 | L34: 156 | M34: 148.45 | N34: 145.22 | O34: -200 | P34: '+--+- | Q34: 0 | R34: 3 | S34: 179 | T34: 21.91 | U34: 46132
A35: 3406 | B35: 玉晶光 | C35: 光電業 | D35: 544 | E35: 41 | F35: 8.15 | G35: '+-+-+ | H35: 12.92 | I35: 0 | J35: 4133 | K35: 3.67 | L35: 517 | M35: 486.1 | N35: 466.95 | O35: 1525 | P35: '+-+-+ | Q35: -422 | R35: 76 | S35: 1165 | T35: 28.19 | U35: 46132
A36: 3611 | B36: 鼎翰 | C36: 電腦及週邊設備業 | D36: 190 | E36: 3 | F36: 1.6 | G36: '-+--+ | H36: 1.07 | I36: 0 | J36: 53 | K36: 0.11 | L36: 187.8 | M36: 187.15 | N36: 186.97 | O36: -16 | P36: '---+- | Q36: 0 | R36: 1 | S36: 4 | T36: 7.55 | U36: 46132
A37: 6606 | B37: 建德工業 | C37: 電機機械 | D37: 24.7 | E37: 0.1 | F37: 0.41 | G37: '+++-+ | H37: 2.07 | I37: 0 | J37: 98 | K37: 0.09 | L37: 24.55 | M37: 24.35 | N37: 24.19 | O37: 19 | P37: '+++++ | Q37: 0 | R37: 1 | S37: 5 | T37: 5.1 | U37: 46132
A38: 8155 | B38: 博智 | C38: 電子零組件業 | D38: 401.5 | E38: 24 | F38: 6.36 | G38: '++-++ | H38: 25.32 | I38: 2 | J38: 4446 | K38: 7.27 | L38: 364 | M38: 333.55 | N38: 296.62 | O38: -449 | P38: '++--- | Q38: 0 | R38: -321 | S38: 2050 | T38: 46.11 | U38: 46132
A39: 2049 | B39: 上銀 | C39: 電機機械 | D39: 293.5 | E39: 2.5 | F39: 0.86 | G39: '++-++ | H39: 16.65 | I39: 1 | J39: 10124 | K39: 2.86 | L39: 284.1 | M39: 263.3 | N39: 247.3 | O39: 69 | P39: '-++++ | Q39: 0 | R39: -210 | S39: 4690 | T39: 46.33 | U39: 46132
A40: 3466 | B40: 德晉 | C40: 通信網路業 | D40: 43.75 | E40: 2.75 | F40: 6.71 | G40: '+++++ | H40: 16.33 | I40: 1 | J40: 2784 | K40: 3.57 | L40: 40.94 | M40: 37.98 | N40: 36.31 | O40: -22 | P40: '++-+- | Q40: 0 | R40: 0 | S40: 937 | T40: 33.66 | U40: 46132
...

Sheet 持股
A1: 是否開始抓取: | B1: 1
A2: 此頁面為目前我手上實際持股 要跟單的每天記得來看狀況 由於後臺每晚9點才會有整體資料 所以必須晚上10點之後來看 (前提是我有更新資料過來) | V2: WIN: | W2: https://winvest.tw/Stock/Symbol/Comment/2330
A3: 此頁面資料永不刪除 只會往下增長 太長會用隱藏方式摺疊 如果要看資料就自己展開 | R3: 一般獲利先抓20%
A4: 規則: | D4: 我買入價 | E4: 手續費+稅 | J4: 依據"題材股" | K4: 買日 | Q4: 賣日 | R4: 開WIN看 | S4: 開WIN看 | T4: 開WIN看 | U4: 開WIN看 | V4: 8ZZ指標 | W4: 開處置王看 | X4: 公告 這是每天要看的重點 有新公告就更新到財報去
A5: =IF(ISBLANK(B5), "", IFERROR(VLOOKUP(B5, STOCKS!A:W, 2, FALSE), "")) | B5: 範例用 | C5: =IFERROR(__xludf.DUMMYFUNCTION("IF(ISBLANK(B5), """", IF(ISBLANK($B$1), """", IMPORTXML('公式表'!$A$2&B5&'公式表'!$A$3, '公式表'!$A$13)))"),"#N/A") -> #N/A | E5: =IF(ISBLANK(D5),"",D5*1.01) | F5: =IF(ISBLANK(B5), "", (C5/D5)-1) -> #N/A | G5: =IF(ISBLANK(B5), "", IFERROR(VLOOKUP(B5, STOCKS!A:W, 10, FALSE), "")) | H5: =IF(ISBLANK(B5), "", IFERROR(VLOOKUP(B5, STOCKS!A:W, 11, FALSE), "")) | I5: =IF(ISBLANK(B5), "", IFERROR(VLOOKUP(B5, STOCKS!A:W, 20, FALSE), "")) | J5: =IF(ISBLANK(B5), "", IFERROR(VLOOKUP(B5, category!A:C, 3, FALSE), "")) | K5: 46078 | O5: =IF(ISBLANK(B5), "", (N5/D5)-1) -> #DIV/0! | Q5: 46078 | X5: =IF(ISBLANK(B5), "", IFERROR(VLOOKUP(B5, STOCKS!A:W, 22, FALSE), ""))
A6: 股票名稱 | B6: 代碼(手填) | C6: 收盤價 | D6: 買進股價 (手填) | E6: 平損價 (1%) | F6: 目前漲幅 | G6: 交易量 (Stock) | H6: 周轉率% (Stock) | I6: 當沖(%) (Stock) | J6: 題材分類 | K6: 買進日期 | L6: 目標價 | M6: 停損價 | N6: 最終 賣出價 | O6: 結算漲幅 | P6: 公式 | Q6: 賣出日期 | R6: EPS比去年同季 增長率(%)(手填) | S6: 最新合併財報 EPS(政府)(手填) | T6: 營收比上月 月增率(%)(手填) | U6: 營收比去年同月 月增率(%)(手填) | V6: 女神操作 (目前)(手填) | W6: 處置風險 (手填) | X6: 最新公告
A7: =IF(ISBLANK(B7), "", IFERROR(VLOOKUP(B7, STOCKS!A:W, 2, FALSE), "")) -> 鈞寶 | B7: 6155 | C7: =IFERROR(__xludf.DUMMYFUNCTION("IF(ISBLANK(B7), """", IF(ISBLANK($B$1), """", IMPORTXML('公式表'!$A$2&B7&'公式表'!$A$3, '公式表'!$A$13)))"),48.0) -> 48 | D7: 57.5 | E7: =IF(ISBLANK(D7),"",D7*1.01) -> 58.075 | F7: =IF(ISBLANK(B7), "", (C7/D7)-1) -> -0.16521739 | G7: =IF(ISBLANK(B7), "", IFERROR(VLOOKUP(B7, STOCKS!A:W, 10, FALSE), "")) -> 1906 | H7: =IF(ISBLANK(B7), "", IFERROR(VLOOKUP(B7, STOCKS!A:W, 11, FALSE), "")) -> 2.17 | I7: =IF(ISBLANK(B7), "", IFERROR(VLOOKUP(B7, STOCKS!A:W, 20, FALSE), "")) -> 44.23 | J7: =IF(ISBLANK(B7), "", IFERROR(VLOOKUP(B7, category!A:C, 3, FALSE), "")) -> 被動元件-MLCC | K7: 46043 | O7: =IF(ISBLANK(B7), "", (N7/D7)-1) -> -1 | P7: 紅綠 | X7: =IF(ISBLANK(B7), "", IFERROR(VLOOKUP(B7, STOCKS!A:W, 22, FALSE), ""))
A8: =IF(ISBLANK(B8), "", IFERROR(VLOOKUP(B8, STOCKS!A:W, 2, FALSE), "")) -> 南茂 | B8: 8150 | C8: =IFERROR(__xludf.DUMMYFUNCTION("IF(ISBLANK(B8), """", IF(ISBLANK($B$1), """", IMPORTXML('公式表'!$A$2&B8&'公式表'!$A$3, '公式表'!$A$13)))"),79.8) -> 79.8 | D8: 69.4 | E8: =IF(ISBLANK(D8),"",D8*1.01) -> 70.094 | F8: =IF(ISBLANK(B8), "", (C8/D8)-1) -> 0.14985591 | G8: =IF(ISBLANK(B8), "", IFERROR(VLOOKUP(B8, STOCKS!A:W, 10, FALSE), "")) -> 43671 | H8: =IF(ISBLANK(B8), "", IFERROR(VLOOKUP(B8, STOCKS!A:W, 11, FALSE), "")) -> 6.2 | I8: =IF(ISBLANK(B8), "", IFERROR(VLOOKUP(B8, STOCKS!A:W, 20, FALSE), "")) -> 52.36 | J8: =IF(ISBLANK(B8), "", IFERROR(VLOOKUP(B8, category!A:C, 3, FALSE), "")) -> 封測 | K8: 46043 | L8: 85 | O8: =IF(ISBLANK(B8), "", (N8/D8)-1) -> -1 | P8: 紅綠 | R8: 0.45 | S8: 0.71 | T8: 0.0395 | U8: 0.3123 | X8: =IF(ISBLANK(B8), "", IFERROR(VLOOKUP(B8, STOCKS!A:W, 22, FALSE), ""))
A9: =IF(ISBLANK(B9), "", IFERROR(VLOOKUP(B9, STOCKS!A:W, 2, FALSE), "")) -> 世界 | B9: 5347 | C9: =IFERROR(__xludf.DUMMYFUNCTION("IF(ISBLANK(B9), """", IF(ISBLANK($B$1), """", IMPORTXML('公式表'!$A$2&B9&'公式表'!$A$3, '公式表'!$A$13)))"),145.0) -> 145 | D9: 148.5 | E9: =IF(ISBLANK(D9),"",D9*1.01) -> 149.985 | F9: =IF(ISBLANK(B9), "", (C9/D9)-1) -> -0.023569024 | G9: =IF(ISBLANK(B9), "", IFERROR(VLOOKUP(B9, STOCKS!A:W, 10, FALSE), "")) -> 68635 | H9: =IF(ISBLANK(B9), "", IFERROR(VLOOKUP(B9, STOCKS!A:W, 11, FALSE), "")) -> 3.68 | I9: =IF(ISBLANK(B9), "", IFERROR(VLOOKUP(B9, STOCKS!A:W, 20, FALSE), "")) -> 53 | J9: =IF(ISBLANK(B9), "", IFERROR(VLOOKUP(B9, category!A:C, 3, FALSE), "")) | K9: 46043 | O9: =IF(ISBLANK(B9), "", (N9/D9)-1) -> -1 | P9: 紅綠 | X9: =IF(ISBLANK(B9), "", IFERROR(VLOOKUP(B9, STOCKS!A:W, 22, FALSE), ""))
A10: =IF(ISBLANK(B10), "", IFERROR(VLOOKUP(B10, STOCKS!A:W, 2, FALSE), "")) -> 華邦電 | B10: 2344 | C10: =IFERROR(__xludf.DUMMYFUNCTION("IF(ISBLANK(B10), """", IF(ISBLANK($B$1), """", IMPORTXML('公式表'!$A$2&B10&'公式表'!$A$3, '公式表'!$A$13)))"),90.6) -> 90.6 | D10: 130 | E10: =IF(ISBLANK(D10),"",D10*1.01) -> 131.3 | F10: =IF(ISBLANK(B10), "", (C10/D10)-1) -> -0.30307692 | G10: =IF(ISBLANK(B10), "", IFERROR(VLOOKUP(B10, STOCKS!A:W, 10, FALSE), "")) -> 164660 | H10: =IF(ISBLANK(B10), "", IFERROR(VLOOKUP(B10, STOCKS!A:W, 11, FALSE), "")) -> 3.66 | I10: =IF(ISBLANK(B10), "", IFERROR(VLOOKUP(B10, STOCKS!A:W, 20, FALSE), "")) -> 37.03 | J10: =IF(ISBLANK(B10), "", IFERROR(VLOOKUP(B10, category!A:C, 3, FALSE), "")) -> DIMM/DRAM | K10: 46052 | M10: 80 | N10: 89.5 | O10: =IF(ISBLANK(B10), "", (N10/D10)-1) -> -0.31153846 | P10: 紅綠 | V10: 已賣出 | X10: =IF(ISBLANK(B10), "", IFERROR(VLOOKUP(B10, STOCKS!A:W, 22, FALSE), ""))
A11: =IF(ISBLANK(B11), "", IFERROR(VLOOKUP(B11, STOCKS!A:W, 2, FALSE), "")) -> 景碩 | B11: 3189 | C11: =IFERROR(__xludf.DUMMYFUNCTION("IF(ISBLANK(B11), """", IF(ISBLANK($B$1), """", IMPORTXML('公式表'!$A$2&B11&'公式表'!$A$3, '公式表'!$A$13)))"),491.5) -> 491.5 | D11: 312.5 | E11: =IF(ISBLANK(D11),"",D11*1.01) -> 315.625 | F11: =IF(ISBLANK(B11), "", (C11/D11)-1) -> 0.5728 | G11: =IF(ISBLANK(B11), "", IFERROR(VLOOKUP(B11, STOCKS!A:W, 10, FALSE), "")) -> 33909 | H11: =IF(ISBLANK(B11), "", IFERROR(VLOOKUP(B11, STOCKS!A:W, 11, FALSE), "")) -> 6.44 | I11: =IF(ISBLANK(B11), "", IFERROR(VLOOKUP(B11, STOCKS!A:W, 20, FALSE), "")) -> 44.08 | J11: =IF(ISBLANK(B11), "", IFERROR(VLOOKUP(B11, category!A:C, 3, FALSE), "")) -> PCB/ABF載板 | K11: 46084 | N11: 348 | O11: =IF(ISBLANK(B11), "", (N11/D11)-1) -> 0.1136 | P11: 紅綠 | Q11: 46099 | X11: =IF(ISBLANK(B11), "", IFERROR(VLOOKUP(B11, STOCKS!A:W, 22, FALSE), ""))
A12: =IF(ISBLANK(B12), "", IFERROR(VLOOKUP(B12, STOCKS!A:W, 2, FALSE), "")) -> 元晶 | B12: 6443 | C12: =IFERROR(__xludf.DUMMYFUNCTION("IF(ISBLANK(B12), """", IF(ISBLANK($B$1), """", IMPORTXML('公式表'!$A$2&B12&'公式表'!$A$3, '公式表'!$A$13)))"),39.5) -> 39.5 | D12: 45.95 | E12: =IF(ISBLANK(D12),"",D12*1.01) -> 46.4095 | F12: =IF(ISBLANK(B12), "", (C12/D12)-1) -> -0.14036997 | G12: =IF(ISBLANK(B12), "", IFERROR(VLOOKUP(B12, STOCKS!A:W, 10, FALSE), "")) -> 7788 | H12: =IF(ISBLANK(B12), "", IFERROR(VLOOKUP(B12, STOCKS!A:W, 11, FALSE), "")) -> 1.52 | I12: =IF(ISBLANK(B12), "", IFERROR(VLOOKUP(B12, STOCKS!A:W, 20, FALSE), "")) -> 0 | J12: =IF(ISBLANK(B12), "", IFERROR(VLOOKUP(B12, category!A:C, 3, FALSE), "")) -> 低軌衛星 | K12: 46104 | N12: 41.3 | O12: =IF(ISBLANK(B12), "", (N12/D12)-1) -> -0.10119695 | P12: 紅綠 | Q12: 46114 | X12: =IF(ISBLANK(B12), "", IFERROR(VLOOKUP(B12, STOCKS!A:W, 22, FALSE), ""))
A13: =IF(ISBLANK(B13), "", IFERROR(VLOOKUP(B13, STOCKS!A:W, 2, FALSE), "")) -> 茂矽 | B13: 2342 | C13: =IFERROR(__xludf.DUMMYFUNCTION("IF(ISBLANK(B13), """", IF(ISBLANK($B$1), """", IMPORTXML('公式表'!$A$2&B13&'公式表'!$A$3, '公式表'!$A$13)))"),33.3) -> 33.3 | D13: 29 | E13: =IF(ISBLANK(D13),"",D13*1.01) -> 29.29 | F13: =IF(ISBLANK(B13), "", (C13/D13)-1) -> 0.14827586 | G13: =IF(ISBLANK(B13), "", IFERROR(VLOOKUP(B13, STOCKS!A:W, 10, FALSE), "")) -> 2493 | H13: =IF(ISBLANK(B13), "", IFERROR(VLOOKUP(B13, STOCKS!A:W, 11, FALSE), "")) -> 1.58 | I13: =IF(ISBLANK(B13), "", IFERROR(VLOOKUP(B13, STOCKS!A:W, 20, FALSE), "")) -> 37.87 | J13: =IF(ISBLANK(B13), "", IFERROR(VLOOKUP(B13, category!A:C, 3, FALSE), "")) -> 矽-sic | K13: 46125 | L13: 36 | O13: =IF(ISBLANK(B13), "", (N13/D13)-1) -> -1 | P13: 循環股 | X13: =IF(ISBLANK(B13), "", IFERROR(VLOOKUP(B13, STOCKS!A:W, 22, FALSE), ""))
A14: =IF(ISBLANK(B14), "", IFERROR(VLOOKUP(B14, STOCKS!A:W, 2, FALSE), "")) -> 大銀微系統 | B14: 4576 | C14: =IFERROR(__xludf.DUMMYFUNCTION("IF(ISBLANK(B14), """", IF(ISBLANK($B$1), """", IMPORTXML('公式表'!$A$2&B14&'公式表'!$A$3, '公式表'!$A$13)))"),198.0) -> 198 | D14: 189.5 | E14: =IF(ISBLANK(D14),"",D14*1.01) -> 191.395 | F14: =IF(ISBLANK(B14), "", (C14/D14)-1) -> 0.044854881 | G14: =IF(ISBLANK(B14), "", IFERROR(VLOOKUP(B14, STOCKS!A:W, 10, FALSE), "")) -> 1696 | H14: =IF(ISBLANK(B14), "", IFERROR(VLOOKUP(B14, STOCKS!A:W, 11, FALSE), "")) -> 1.42 | I14: =IF(ISBLANK(B14), "", IFERROR(VLOOKUP(B14, STOCKS!A:W, 20, FALSE), "")) -> 0 | J14: =IF(ISBLANK(B14), "", IFERROR(VLOOKUP(B14, category!A:C, 3, FALSE), "")) | K14: 46126 | L14: 1200 | O14: =IF(ISBLANK(B14), "", (N14/D14)-1) -> -1 | P14: 外部消息 | X14: =IF(ISBLANK(B14), "", IFERROR(VLOOKUP(B14, STOCKS!A:W, 22, FALSE), ""))

Sheet 紅綠
A1: 更新日期 | B1: 45951 | D1: Note: | E1: 請注意平日成交量
C2: 選股符合打V | D2: 參考 | G2: V | I2: 參考 | J2: V | K2: V | L2: 參考 | N2: 參考 | P2: V | S2: 參考
C3: 選股策略: | D3: <150 | G3: -- | I3: >=3 | J3: >2000 | K3: >5 SORT | L3: MA5逼近MA10 | N3: D<N | P3: 最後兩天++ | S3: >成交*50%
A4: ID | B4: Name | C4: Type | D4: 收盤價 | E4: 價差 | F4: 漲幅 (%) | G4: 五日+- | H4: 五日漲幅 (%) | I4: 漲停 歷史 | J4: 交易量 (張) | K4: 周轉率 (%) | L4: MA5 | M4: MA10 | N4: MA20 | O4: 外資 (張) | P4: 外資 五日+- | Q4: 投信 (張) | R4: 自營 (張) | S4: 當沖 (張) | T4: 當沖 (%) | U4: Date | V4: News | W4: ExDate
A5: 2485 | B5: 兆赫 | C5: 通信網路業 | D5: 71 | E5: -6.7 | F5: -8.62 | G5: '-+--- | H5: -12.44 | I5: 1 | J5: 39738 | K5: 12.51 | L5: 77.2 | M5: 75.63 | N5: 77.09 | O5: 390 | P5: -+--+ | Q5: 139 | R5: -601 | S5: 16965 | T5: 42.69 | U5: 46132
A6: 6127 | B6: 九豪 | C6: 電子零組件業 | D6: 48 | E6: -2.3 | F6: -4.57 | G6: '+-+-- | H6: 9.58 | I6: 2 | J6: 13193 | K6: 12.21 | L6: 49.03 | M6: 44.96 | N6: 43.7 | O6: -43 | P6: +-+-- | Q6: 0 | R6: -19 | S6: 3896 | T6: 29.53 | U6: 46132
A7: 1528 | B7: 恩德 | C7: 電機機械 | D7: 28.2 | E7: -1 | F7: -3.42 | G7: '++--- | H7: 3.63 | I7: 3 | J7: 17835 | K7: 9.32 | L7: 29.03 | M7: 28.08 | N7: 26.07 | O7: 374 | P7: ++-++ | Q7: -22 | R7: 4 | S7: 6903 | T7: 38.7 | U7: 46132
A8: 2367 | B8: 燿華 | C8: 電子零組件業 | D8: 65.6 | E8: -2.9 | F8: -4.23 | G8: '-+--- | H8: -11.85 | I8: 1 | J8: 61759 | K8: 8.74 | L8: 69.72 | M8: 72.11 | N8: 72.91 | O8: 6083 | P8: -+--+ | Q8: -431 | R8: -808 | S8: 24374 | T8: 39.47 | U8: 46132
A9: 2337 | B9: 旺宏 | C9: 半導體業 | D9: 120.5 | E9: -10.5 | F9: -8.02 | G9: '+---- | H9: -19.15 | I9: 2 | J9: 170786 | K9: 8.62 | L9: 137.6 | M9: 141 | N9: 137.47 | O9: 1245 | P9: +-+-+ | Q9: -5950 | R9: -482 | S9: 82406 | T9: 48.25 | U9: 46132

Sheet 紅綠-績優股
C1: 選股符合打V | D1: 參考 | G1: V | I1: 參考 | J1: V | K1: V | L1: 參考 | N1: 參考 | P1: V | S1: 參考 | V1: https://mops.twse.com.tw/mops/#/web/t05sr01_1
C2: 條件: | D2: <150 | G2: 為 - - | I2: >=3 | J2: >2000 | K2: >5 | L2: MA5逼近MA10 | N2: D<N | P2: 為 + + | S2: >成交*50%
A3: ID | B3: Name | C3: Type | D3: 收盤價 | E3: 價差 | F3: 漲幅(%) | G3: 五日+- | H3: 五日漲幅 (%) | I3: 漲停歷史 | J3: 交易量 (張) | K3: 周轉率 (%) | L3: MA5 | M3: MA10 | N3: MA20 | O3: 外資 (張) | P3: 外資 五日+- | Q3: 投信 (張) | R3: 自營 (張) | S3: 當沖 (張) | T3: 當沖 (%) | U3: Date | V3: 公告 | W3: 第 2 欄 | X3: 第 3 欄 | Y3: 第 4 欄 | Z3: 第 26 欄
A4: 1528 | B4: =IF(ISBLANK(A4), "", IFERROR(VLOOKUP(A4, STOCKS!A:W, 2, FALSE), "")) -> 恩德 | C4: =IF(ISBLANK(A4), "", IFERROR(VLOOKUP(A4, STOCKS!A:W, 3, FALSE), "")) -> 電機機械 | D4: =IF(ISBLANK(A4), "", IFERROR(VLOOKUP(A4, STOCKS!A:W, 4, FALSE), "")) -> 28.2 | E4: =IF(ISBLANK(A4), "", IFERROR(VLOOKUP(A4, STOCKS!A:W, 5, FALSE), "")) -> -1 | F4: =IF(ISBLANK(A4), "", IFERROR(VLOOKUP(A4, STOCKS!A:W, 6, FALSE), "")) -> -3.42 | G4: =IF(ISBLANK(A4), "", IFERROR(VLOOKUP(A4, STOCKS!A:W, 7, FALSE), "")) -> '++--- | H4: =IF(ISBLANK(A4), "", IFERROR(VLOOKUP(A4, STOCKS!A:W, 8, FALSE), "")) -> 3.63 | I4: =IF(ISBLANK(A4), "", IFERROR(VLOOKUP(A4, STOCKS!A:W, 9, FALSE), "")) -> 3 | J4: =IF(ISBLANK(A4), "", IFERROR(VLOOKUP(A4, STOCKS!A:W, 10, FALSE), "")) -> 17835 | K4: =IF(ISBLANK(A4), "", IFERROR(VLOOKUP(A4, STOCKS!A:W, 11, FALSE), "")) -> 9.32 | L4: =IF(ISBLANK(A4), "", IFERROR(VLOOKUP(A4, STOCKS!A:W, 12, FALSE), "")) -> 29.03 | M4: =IF(ISBLANK(A4), "", IFERROR(VLOOKUP(A4, STOCKS!A:W, 13, FALSE), "")) -> 28.08 | N4: =IF(ISBLANK(A4), "", IFERROR(VLOOKUP(A4, STOCKS!A:W, 14, FALSE), "")) -> 26.07 | O4: =IF(ISBLANK(A4), "", IFERROR(VLOOKUP(A4, STOCKS!A:W, 15, FALSE), "")) -> 374 | P4: =IF(ISBLANK(A4), "", IFERROR(VLOOKUP(A4, STOCKS!A:W, 16, FALSE), "")) -> '++-++ | Q4: =IF(ISBLANK(A4), "", IFERROR(VLOOKUP(A4, STOCKS!A:W, 17, FALSE), "")) -> -22 | R4: =IF(ISBLANK(A4), "", IFERROR(VLOOKUP(A4, STOCKS!A:W, 18, FALSE), "")) -> 4 | S4: =IF(ISBLANK(A4), "", IFERROR(VLOOKUP(A4, STOCKS!A:W, 19, FALSE), "")) -> 6903 | T4: =IF(ISBLANK(A4), "", IFERROR(VLOOKUP(A4, STOCKS!A:W, 20, FALSE), "")) -> 38.7 | U4: =IF(ISBLANK(A4), "", IFERROR(VLOOKUP(A4, STOCKS!A:W, 21, FALSE), "")) -> 46132 | V4: =IF(ISBLANK(A4), "", IFERROR(VLOOKUP(A4, STOCKS!A:W, 22, FALSE), ""))
A5: 1569 | B5: =IF(ISBLANK(A5), "", IFERROR(VLOOKUP(A5, STOCKS!A:W, 2, FALSE), "")) -> 濱川 | C5: =IF(ISBLANK(A5), "", IFERROR(VLOOKUP(A5, STOCKS!A:W, 3, FALSE), "")) -> 電腦及週邊設備業 | D5: =IF(ISBLANK(A5), "", IFERROR(VLOOKUP(A5, STOCKS!A:W, 4, FALSE), "")) -> 52.3 | E5: =IF(ISBLANK(A5), "", IFERROR(VLOOKUP(A5, STOCKS!A:W, 5, FALSE), "")) -> -0.2 | F5: =IF(ISBLANK(A5), "", IFERROR(VLOOKUP(A5, STOCKS!A:W, 6, FALSE), "")) -> -0.38 | G5: =IF(ISBLANK(A5), "", IFERROR(VLOOKUP(A5, STOCKS!A:W, 7, FALSE), "")) -> '----- | H5: =IF(ISBLANK(A5), "", IFERROR(VLOOKUP(A5, STOCKS!A:W, 8, FALSE), "")) -> -5.89 | I5: =IF(ISBLANK(A5), "", IFERROR(VLOOKUP(A5, STOCKS!A:W, 9, FALSE), "")) -> 1 | J5: =IF(ISBLANK(A5), "", IFERROR(VLOOKUP(A5, STOCKS!A:W, 10, FALSE), "")) -> 815 | K5: =IF(ISBLANK(A5), "", IFERROR(VLOOKUP(A5, STOCKS!A:W, 11, FALSE), "")) -> 0.57 | L5: =IF(ISBLANK(A5), "", IFERROR(VLOOKUP(A5, STOCKS!A:W, 12, FALSE), "")) -> 53.14 | M5: =IF(ISBLANK(A5), "", IFERROR(VLOOKUP(A5, STOCKS!A:W, 13, FALSE), "")) -> 53.12 | N5: =IF(ISBLANK(A5), "", IFERROR(VLOOKUP(A5, STOCKS!A:W, 14, FALSE), "")) -> 51.56 | O5: =IF(ISBLANK(A5), "", IFERROR(VLOOKUP(A5, STOCKS!A:W, 15, FALSE), "")) -> 38 | P5: =IF(ISBLANK(A5), "", IFERROR(VLOOKUP(A5, STOCKS!A:W, 16, FALSE), "")) -> '----+ | Q5: =IF(ISBLANK(A5), "", IFERROR(VLOOKUP(A5, STOCKS!A:W, 17, FALSE), "")) -> 0 | R5: =IF(ISBLANK(A5), "", IFERROR(VLOOKUP(A5, STOCKS!A:W, 18, FALSE), "")) -> 0 | S5: =IF(ISBLANK(A5), "", IFERROR(VLOOKUP(A5, STOCKS!A:W, 19, FALSE), "")) -> 163 | T5: =IF(ISBLANK(A5), "", IFERROR(VLOOKUP(A5, STOCKS!A:W, 20, FALSE), "")) -> 20 | U5: =IF(ISBLANK(A5), "", IFERROR(VLOOKUP(A5, STOCKS!A:W, 21, FALSE), "")) -> 46132 | V5: =IF(ISBLANK(A5), "", IFERROR(VLOOKUP(A5, STOCKS!A:W, 22, FALSE), ""))
A6: 2615 | B6: =IF(ISBLANK(A6), "", IFERROR(VLOOKUP(A6, STOCKS!A:W, 2, FALSE), "")) -> 萬海 | C6: =IF(ISBLANK(A6), "", IFERROR(VLOOKUP(A6, STOCKS!A:W, 3, FALSE), "")) -> 航運業 | D6: =IF(ISBLANK(A6), "", IFERROR(VLOOKUP(A6, STOCKS!A:W, 4, FALSE), "")) -> 73.7 | E6: =IF(ISBLANK(A6), "", IFERROR(VLOOKUP(A6, STOCKS!A:W, 5, FALSE), "")) -> -1.6 | F6: =IF(ISBLANK(A6), "", IFERROR(VLOOKUP(A6, STOCKS!A:W, 6, FALSE), "")) -> -2.12 | G6: =IF(ISBLANK(A6), "", IFERROR(VLOOKUP(A6, STOCKS!A:W, 7, FALSE), "")) -> '-+--- | H6: =IF(ISBLANK(A6), "", IFERROR(VLOOKUP(A6, STOCKS!A:W, 8, FALSE), "")) -> -3.65 | I6: =IF(ISBLANK(A6), "", IFERROR(VLOOKUP(A6, STOCKS!A:W, 9, FALSE), "")) -> 0 | J6: =IF(ISBLANK(A6), "", IFERROR(VLOOKUP(A6, STOCKS!A:W, 10, FALSE), "")) -> 8584 | K6: =IF(ISBLANK(A6), "", IFERROR(VLOOKUP(A6, STOCKS!A:W, 11, FALSE), "")) -> 0.31 | L6: =IF(ISBLANK(A6), "", IFERROR(VLOOKUP(A6, STOCKS!A:W, 12, FALSE), "")) -> 75.94 | M6: =IF(ISBLANK(A6), "", IFERROR(VLOOKUP(A6, STOCKS!A:W, 13, FALSE), "")) -> 76.98 | N6: =IF(ISBLANK(A6), "", IFERROR(VLOOKUP(A6, STOCKS!A:W, 14, FALSE), "")) -> 76.79 | O6: =IF(ISBLANK(A6), "", IFERROR(VLOOKUP(A6, STOCKS!A:W, 15, FALSE), "")) -> -1134 | P6: =IF(ISBLANK(A6), "", IFERROR(VLOOKUP(A6, STOCKS!A:W, 16, FALSE), "")) -> '+++-- | Q6: =IF(ISBLANK(A6), "", IFERROR(VLOOKUP(A6, STOCKS!A:W, 17, FALSE), "")) -> -490 | R6: =IF(ISBLANK(A6), "", IFERROR(VLOOKUP(A6, STOCKS!A:W, 18, FALSE), "")) -> -58 | S6: =IF(ISBLANK(A6), "", IFERROR(VLOOKUP(A6, STOCKS!A:W, 19, FALSE), "")) -> 1552 | T6: =IF(ISBLANK(A6), "", IFERROR(VLOOKUP(A6, STOCKS!A:W, 20, FALSE), "")) -> 18.08 | U6: =IF(ISBLANK(A6), "", IFERROR(VLOOKUP(A6, STOCKS!A:W, 21, FALSE), "")) -> 46132 | V6: =IF(ISBLANK(A6), "", IFERROR(VLOOKUP(A6, STOCKS!A:W, 22, FALSE), ""))
A7: 2316 | B7: =IF(ISBLANK(A7), "", IFERROR(VLOOKUP(A7, STOCKS!A:W, 2, FALSE), "")) -> 楠梓電 | C7: =IF(ISBLANK(A7), "", IFERROR(VLOOKUP(A7, STOCKS!A:W, 3, FALSE), "")) -> 電子零組件業 | D7: =IF(ISBLANK(A7), "", IFERROR(VLOOKUP(A7, STOCKS!A:W, 4, FALSE), "")) -> 112 | E7: =IF(ISBLANK(A7), "", IFERROR(VLOOKUP(A7, STOCKS!A:W, 5, FALSE), "")) -> -2.5 | F7: =IF(ISBLANK(A7), "", IFERROR(VLOOKUP(A7, STOCKS!A:W, 6, FALSE), "")) -> -2.18 | G7: =IF(ISBLANK(A7), "", IFERROR(VLOOKUP(A7, STOCKS!A:W, 7, FALSE), "")) -> '+---- | H7: =IF(ISBLANK(A7), "", IFERROR(VLOOKUP(A7, STOCKS!A:W, 8, FALSE), "")) -> -0.71 | I7: =IF(ISBLANK(A7), "", IFERROR(VLOOKUP(A7, STOCKS!A:W, 9, FALSE), "")) -> 2 | J7: =IF(ISBLANK(A7), "", IFERROR(VLOOKUP(A7, STOCKS!A:W, 10, FALSE), "")) -> 8250 | K7: =IF(ISBLANK(A7), "", IFERROR(VLOOKUP(A7, STOCKS!A:W, 11, FALSE), "")) -> 4.51 | L7: =IF(ISBLANK(A7), "", IFERROR(VLOOKUP(A7, STOCKS!A:W, 12, FALSE), "")) -> 115 | M7: =IF(ISBLANK(A7), "", IFERROR(VLOOKUP(A7, STOCKS!A:W, 13, FALSE), "")) -> 110.42 | N7: =IF(ISBLANK(A7), "", IFERROR(VLOOKUP(A7, STOCKS!A:W, 14, FALSE), "")) -> 106.35 | O7: =IF(ISBLANK(A7), "", IFERROR(VLOOKUP(A7, STOCKS!A:W, 15, FALSE), "")) -> -2343 | P7: =IF(ISBLANK(A7), "", IFERROR(VLOOKUP(A7, STOCKS!A:W, 16, FALSE), "")) -> '--+-- | Q7: =IF(ISBLANK(A7), "", IFERROR(VLOOKUP(A7, STOCKS!A:W, 17, FALSE), "")) -> -56 | R7: =IF(ISBLANK(A7), "", IFERROR(VLOOKUP(A7, STOCKS!A:W, 18, FALSE), "")) -> -99 | S7: =IF(ISBLANK(A7), "", IFERROR(VLOOKUP(A7, STOCKS!A:W, 19, FALSE), "")) -> 3276 | T7: =IF(ISBLANK(A7), "", IFERROR(VLOOKUP(A7, STOCKS!A:W, 20, FALSE), "")) -> 39.71 | U7: =IF(ISBLANK(A7), "", IFERROR(VLOOKUP(A7, STOCKS!A:W, 21, FALSE), "")) -> 46132 | V7: =IF(ISBLANK(A7), "", IFERROR(VLOOKUP(A7, STOCKS!A:W, 22, FALSE), ""))
A8: 3379 | B8: =IF(ISBLANK(A8), "", IFERROR(VLOOKUP(A8, STOCKS!A:W, 2, FALSE), "")) -> 彬台 | C8: =IF(ISBLANK(A8), "", IFERROR(VLOOKUP(A8, STOCKS!A:W, 3, FALSE), "")) -> 電機機械 | D8: =IF(ISBLANK(A8), "", IFERROR(VLOOKUP(A8, STOCKS!A:W, 4, FALSE), "")) -> 37.8 | E8: =IF(ISBLANK(A8), "", IFERROR(VLOOKUP(A8, STOCKS!A:W, 5, FALSE), "")) -> 0.5 | F8: =IF(ISBLANK(A8), "", IFERROR(VLOOKUP(A8, STOCKS!A:W, 6, FALSE), "")) -> 1.34 | G8: =IF(ISBLANK(A8), "", IFERROR(VLOOKUP(A8, STOCKS!A:W, 7, FALSE), "")) -> '+++++ | H8: =IF(ISBLANK(A8), "", IFERROR(VLOOKUP(A8, STOCKS!A:W, 8, FALSE), "")) -> 7.38 | I8: =IF(ISBLANK(A8), "", IFERROR(VLOOKUP(A8, STOCKS!A:W, 9, FALSE), "")) -> 0 | J8: =IF(ISBLANK(A8), "", IFERROR(VLOOKUP(A8, STOCKS!A:W, 10, FALSE), "")) -> 307 | K8: =IF(ISBLANK(A8), "", IFERROR(VLOOKUP(A8, STOCKS!A:W, 11, FALSE), "")) -> 0.81 | L8: =IF(ISBLANK(A8), "", IFERROR(VLOOKUP(A8, STOCKS!A:W, 12, FALSE), "")) -> 37.21 | M8: =IF(ISBLANK(A8), "", IFERROR(VLOOKUP(A8, STOCKS!A:W, 13, FALSE), "")) -> 37.01 | N8: =IF(ISBLANK(A8), "", IFERROR(VLOOKUP(A8, STOCKS!A:W, 14, FALSE), "")) -> 37.47 | O8: =IF(ISBLANK(A8), "", IFERROR(VLOOKUP(A8, STOCKS!A:W, 15, FALSE), "")) -> 60 | P8: =IF(ISBLANK(A8), "", IFERROR(VLOOKUP(A8, STOCKS!A:W, 16, FALSE), "")) -> '+-+++ | Q8: =IF(ISBLANK(A8), "", IFERROR(VLOOKUP(A8, STOCKS!A:W, 17, FALSE), "")) -> 0 | R8: =IF(ISBLANK(A8), "", IFERROR(VLOOKUP(A8, STOCKS!A:W, 18, FALSE), "")) -> -11 | S8: =IF(ISBLANK(A8), "", IFERROR(VLOOKUP(A8, STOCKS!A:W, 19, FALSE), "")) -> 73 | T8: =IF(ISBLANK(A8), "", IFERROR(VLOOKUP(A8, STOCKS!A:W, 20, FALSE), "")) -> 23.78 | U8: =IF(ISBLANK(A8), "", IFERROR(VLOOKUP(A8, STOCKS!A:W, 21, FALSE), "")) -> 46132 | V8: =IF(ISBLANK(A8), "", IFERROR(VLOOKUP(A8, STOCKS!A:W, 22, FALSE), ""))
A9: 3528 | B9: =IF(ISBLANK(A9), "", IFERROR(VLOOKUP(A9, STOCKS!A:W, 2, FALSE), "")) -> 安馳 | C9: =IF(ISBLANK(A9), "", IFERROR(VLOOKUP(A9, STOCKS!A:W, 3, FALSE), "")) -> 電子通路業 | D9: =IF(ISBLANK(A9), "", IFERROR(VLOOKUP(A9, STOCKS!A:W, 4, FALSE), "")) -> 72 | E9: =IF(ISBLANK(A9), "", IFERROR(VLOOKUP(A9, STOCKS!A:W, 5, FALSE), "")) -> -0.3 | F9: =IF(ISBLANK(A9), "", IFERROR(VLOOKUP(A9, STOCKS!A:W, 6, FALSE), "")) -> -0.41 | G9: =IF(ISBLANK(A9), "", IFERROR(VLOOKUP(A9, STOCKS!A:W, 7, FALSE), "")) -> '+--+- | H9: =IF(ISBLANK(A9), "", IFERROR(VLOOKUP(A9, STOCKS!A:W, 8, FALSE), "")) -> 2.74 | I9: =IF(ISBLANK(A9), "", IFERROR(VLOOKUP(A9, STOCKS!A:W, 9, FALSE), "")) -> 0 | J9: =IF(ISBLANK(A9), "", IFERROR(VLOOKUP(A9, STOCKS!A:W, 10, FALSE), "")) -> 264 | K9: =IF(ISBLANK(A9), "", IFERROR(VLOOKUP(A9, STOCKS!A:W, 11, FALSE), "")) -> 0.4 | L9: =IF(ISBLANK(A9), "", IFERROR(VLOOKUP(A9, STOCKS!A:W, 12, FALSE), "")) -> 71.3 | M9: =IF(ISBLANK(A9), "", IFERROR(VLOOKUP(A9, STOCKS!A:W, 13, FALSE), "")) -> 69.43 | N9: =IF(ISBLANK(A9), "", IFERROR(VLOOKUP(A9, STOCKS!A:W, 14, FALSE), "")) -> 66.32 | O9: =IF(ISBLANK(A9), "", IFERROR(VLOOKUP(A9, STOCKS!A:W, 15, FALSE), "")) -> -48 | P9: =IF(ISBLANK(A9), "", IFERROR(VLOOKUP(A9, STOCKS!A:W, 16, FALSE), "")) -> '++++- | Q9: =IF(ISBLANK(A9), "", IFERROR(VLOOKUP(A9, STOCKS!A:W, 17, FALSE), "")) -> 0 | R9: =IF(ISBLANK(A9), "", IFERROR(VLOOKUP(A9, STOCKS!A:W, 18, FALSE), "")) -> 0 | S9: =IF(ISBLANK(A9), "", IFERROR(VLOOKUP(A9, STOCKS!A:W, 19, FALSE), "")) -> 39 | T9: =IF(ISBLANK(A9), "", IFERROR(VLOOKUP(A9, STOCKS!A:W, 20, FALSE), "")) -> 14.77 | U9: =IF(ISBLANK(A9), "", IFERROR(VLOOKUP(A9, STOCKS!A:W, 21, FALSE), "")) -> 46132 | V9: =IF(ISBLANK(A9), "", IFERROR(VLOOKUP(A9, STOCKS!A:W, 22, FALSE), ""))
A10: 3645 | B10: =IF(ISBLANK(A10), "", IFERROR(VLOOKUP(A10, STOCKS!A:W, 2, FALSE), "")) -> 達邁 | C10: =IF(ISBLANK(A10), "", IFERROR(VLOOKUP(A10, STOCKS!A:W, 3, FALSE), "")) -> 電子零組件業 | D10: =IF(ISBLANK(A10), "", IFERROR(VLOOKUP(A10, STOCKS!A:W, 4, FALSE), "")) -> 114.5 | E10: =IF(ISBLANK(A10), "", IFERROR(VLOOKUP(A10, STOCKS!A:W, 5, FALSE), "")) -> 10 | F10: =IF(ISBLANK(A10), "", IFERROR(VLOOKUP(A10, STOCKS!A:W, 6, FALSE), "")) -> 9.57 | G10: =IF(ISBLANK(A10), "", IFERROR(VLOOKUP(A10, STOCKS!A:W, 7, FALSE), "")) -> '-++++ | H10: =IF(ISBLANK(A10), "", IFERROR(VLOOKUP(A10, STOCKS!A:W, 8, FALSE), "")) -> 24.55 | I10: =IF(ISBLANK(A10), "", IFERROR(VLOOKUP(A10, STOCKS!A:W, 9, FALSE), "")) -> 4 | J10: =IF(ISBLANK(A10), "", IFERROR(VLOOKUP(A10, STOCKS!A:W, 10, FALSE), "")) -> 19720 | K10: =IF(ISBLANK(A10), "", IFERROR(VLOOKUP(A10, STOCKS!A:W, 11, FALSE), "")) -> 14.42 | L10: =IF(ISBLANK(A10), "", IFERROR(VLOOKUP(A10, STOCKS!A:W, 12, FALSE), "")) -> 100.38 | M10: =IF(ISBLANK(A10), "", IFERROR(VLOOKUP(A10, STOCKS!A:W, 13, FALSE), "")) -> 89.52 | N10: =IF(ISBLANK(A10), "", IFERROR(VLOOKUP(A10, STOCKS!A:W, 14, FALSE), "")) -> 82.4 | O10: =IF(ISBLANK(A10), "", IFERROR(VLOOKUP(A10, STOCKS!A:W, 15, FALSE), "")) -> -1499 | P10: =IF(ISBLANK(A10), "", IFERROR(VLOOKUP(A10, STOCKS!A:W, 16, FALSE), "")) -> '+---- | Q10: =IF(ISBLANK(A10), "", IFERROR(VLOOKUP(A10, STOCKS!A:W, 17, FALSE), "")) -> 0 | R10: =IF(ISBLANK(A10), "", IFERROR(VLOOKUP(A10, STOCKS!A:W, 18, FALSE), "")) -> 117 | S10: =IF(ISBLANK(A10), "", IFERROR(VLOOKUP(A10, STOCKS!A:W, 19, FALSE), "")) -> 9410 | T10: =IF(ISBLANK(A10), "", IFERROR(VLOOKUP(A10, STOCKS!A:W, 20, FALSE), "")) -> 47.72 | U10: =IF(ISBLANK(A10), "", IFERROR(VLOOKUP(A10, STOCKS!A:W, 21, FALSE), "")) -> 46132 | V10: =IF(ISBLANK(A10), "", IFERROR(VLOOKUP(A10, STOCKS!A:W, 22, FALSE), ""))
A11: 3709 | B11: =IF(ISBLANK(A11), "", IFERROR(VLOOKUP(A11, STOCKS!A:W, 2, FALSE), "")) -> 鑫聯大投控 | C11: =IF(ISBLANK(A11), "", IFERROR(VLOOKUP(A11, STOCKS!A:W, 3, FALSE), "")) -> 電腦及週邊設備業 | D11: =IF(ISBLANK(A11), "", IFERROR(VLOOKUP(A11, STOCKS!A:W, 4, FALSE), "")) -> 70.3 | E11: =IF(ISBLANK(A11), "", IFERROR(VLOOKUP(A11, STOCKS!A:W, 5, FALSE), "")) -> -1 | F11: =IF(ISBLANK(A11), "", IFERROR(VLOOKUP(A11, STOCKS!A:W, 6, FALSE), "")) -> -1.4 | G11: =IF(ISBLANK(A11), "", IFERROR(VLOOKUP(A11, STOCKS!A:W, 7, FALSE), "")) -> '+--+- | H11: =IF(ISBLANK(A11), "", IFERROR(VLOOKUP(A11, STOCKS!A:W, 8, FALSE), "")) -> 2.79 | I11: =IF(ISBLANK(A11), "", IFERROR(VLOOKUP(A11, STOCKS!A:W, 9, FALSE), "")) -> 0 | J11: =IF(ISBLANK(A11), "", IFERROR(VLOOKUP(A11, STOCKS!A:W, 10, FALSE), "")) -> 2732 | K11: =IF(ISBLANK(A11), "", IFERROR(VLOOKUP(A11, STOCKS!A:W, 11, FALSE), "")) -> 2.18 | L11: =IF(ISBLANK(A11), "", IFERROR(VLOOKUP(A11, STOCKS!A:W, 12, FALSE), "")) -> 71.12 | M11: =IF(ISBLANK(A11), "", IFERROR(VLOOKUP(A11, STOCKS!A:W, 13, FALSE), "")) -> 69.48 | N11: =IF(ISBLANK(A11), "", IFERROR(VLOOKUP(A11, STOCKS!A:W, 14, FALSE), "")) -> 67.94 | O11: =IF(ISBLANK(A11), "", IFERROR(VLOOKUP(A11, STOCKS!A:W, 15, FALSE), "")) -> -672 | P11: =IF(ISBLANK(A11), "", IFERROR(VLOOKUP(A11, STOCKS!A:W, 16, FALSE), "")) -> '+--+- | Q11: =IF(ISBLANK(A11), "", IFERROR(VLOOKUP(A11, STOCKS!A:W, 17, FALSE), "")) -> 0 | R11: =IF(ISBLANK(A11), "", IFERROR(VLOOKUP(A11, STOCKS!A:W, 18, FALSE), "")) -> -2 | S11: =IF(ISBLANK(A11), "", IFERROR(VLOOKUP(A11, STOCKS!A:W, 19, FALSE), "")) -> 1063 | T11: =IF(ISBLANK(A11), "", IFERROR(VLOOKUP(A11, STOCKS!A:W, 20, FALSE), "")) -> 38.91 | U11: =IF(ISBLANK(A11), "", IFERROR(VLOOKUP(A11, STOCKS!A:W, 21, FALSE), "")) -> 46132 | V11: =IF(ISBLANK(A11), "", IFERROR(VLOOKUP(A11, STOCKS!A:W, 22, FALSE), "")) -> 公告本公司董事會決議修訂115年股東常會召集事由 (修訂其他事項)
A12: 4541 | B12: =IF(ISBLANK(A12), "", IFERROR(VLOOKUP(A12, STOCKS!A:W, 2, FALSE), "")) -> 晟田 | C12: =IF(ISBLANK(A12), "", IFERROR(VLOOKUP(A12, STOCKS!A:W, 3, FALSE), "")) -> 其他業 | D12: =IF(ISBLANK(A12), "", IFERROR(VLOOKUP(A12, STOCKS!A:W, 4, FALSE), "")) -> 49.35 | E12: =IF(ISBLANK(A12), "", IFERROR(VLOOKUP(A12, STOCKS!A:W, 5, FALSE), "")) -> 1.05 | F12: =IF(ISBLANK(A12), "", IFERROR(VLOOKUP(A12, STOCKS!A:W, 6, FALSE), "")) -> 2.17 | G12: =IF(ISBLANK(A12), "", IFERROR(VLOOKUP(A12, STOCKS!A:W, 7, FALSE), "")) -> '+-+++ | H12: =IF(ISBLANK(A12), "", IFERROR(VLOOKUP(A12, STOCKS!A:W, 8, FALSE), "")) -> 6.37 | I12: =IF(ISBLANK(A12), "", IFERROR(VLOOKUP(A12, STOCKS!A:W, 9, FALSE), "")) -> 1 | J12: =IF(ISBLANK(A12), "", IFERROR(VLOOKUP(A12, STOCKS!A:W, 10, FALSE), "")) -> 3379 | K12: =IF(ISBLANK(A12), "", IFERROR(VLOOKUP(A12, STOCKS!A:W, 11, FALSE), "")) -> 5 | L12: =IF(ISBLANK(A12), "", IFERROR(VLOOKUP(A12, STOCKS!A:W, 12, FALSE), "")) -> 47.72 | M12: =IF(ISBLANK(A12), "", IFERROR(VLOOKUP(A12, STOCKS!A:W, 13, FALSE), "")) -> 45.71 | N12: =IF(ISBLANK(A12), "", IFERROR(VLOOKUP(A12, STOCKS!A:W, 14, FALSE), "")) -> 43.71 | O12: =IF(ISBLANK(A12), "", IFERROR(VLOOKUP(A12, STOCKS!A:W, 15, FALSE), "")) -> 438 | P12: =IF(ISBLANK(A12), "", IFERROR(VLOOKUP(A12, STOCKS!A:W, 16, FALSE), "")) -> '+++++ | Q12: =IF(ISBLANK(A12), "", IFERROR(VLOOKUP(A12, STOCKS!A:W, 17, FALSE), "")) -> 0 | R12: =IF(ISBLANK(A12), "", IFERROR(VLOOKUP(A12, STOCKS!A:W, 18, FALSE), "")) -> 2 | S12: =IF(ISBLANK(A12), "", IFERROR(VLOOKUP(A12, STOCKS!A:W, 19, FALSE), "")) -> 1176 | T12: =IF(ISBLANK(A12), "", IFERROR(VLOOKUP(A12, STOCKS!A:W, 20, FALSE), "")) -> 34.8 | U12: =IF(ISBLANK(A12), "", IFERROR(VLOOKUP(A12, STOCKS!A:W, 21, FALSE), "")) -> 46132 | V12: =IF(ISBLANK(A12), "", IFERROR(VLOOKUP(A12, STOCKS!A:W, 22, FALSE), ""))
A13: 5201 | B13: =IF(ISBLANK(A13), "", IFERROR(VLOOKUP(A13, STOCKS!A:W, 2, FALSE), "")) -> 凱衛 | C13: =IF(ISBLANK(A13), "", IFERROR(VLOOKUP(A13, STOCKS!A:W, 3, FALSE), "")) -> 資訊服務業 | D13: =IF(ISBLANK(A13), "", IFERROR(VLOOKUP(A13, STOCKS!A:W, 4, FALSE), "")) -> 37.15 | E13: =IF(ISBLANK(A13), "", IFERROR(VLOOKUP(A13, STOCKS!A:W, 5, FALSE), "")) -> -1.95 | F13: =IF(ISBLANK(A13), "", IFERROR(VLOOKUP(A13, STOCKS!A:W, 6, FALSE), "")) -> -4.99 | G13: =IF(ISBLANK(A13), "", IFERROR(VLOOKUP(A13, STOCKS!A:W, 7, FALSE), "")) -> '++--- | H13: =IF(ISBLANK(A13), "", IFERROR(VLOOKUP(A13, STOCKS!A:W, 8, FALSE), "")) -> -4.21 | I13: =IF(ISBLANK(A13), "", IFERROR(VLOOKUP(A13, STOCKS!A:W, 9, FALSE), "")) -> 0 | J13: =IF(ISBLANK(A13), "", IFERROR(VLOOKUP(A13, STOCKS!A:W, 10, FALSE), "")) -> 237 | K13: =IF(ISBLANK(A13), "", IFERROR(VLOOKUP(A13, STOCKS!A:W, 11, FALSE), "")) -> 0.61 | L13: =IF(ISBLANK(A13), "", IFERROR(VLOOKUP(A13, STOCKS!A:W, 12, FALSE), "")) -> 38.86 | M13: =IF(ISBLANK(A13), "", IFERROR(VLOOKUP(A13, STOCKS!A:W, 13, FALSE), "")) -> 38.87 | N13: =IF(ISBLANK(A13), "", IFERROR(VLOOKUP(A13, STOCKS!A:W, 14, FALSE), "")) -> 39.08 | O13: =IF(ISBLANK(A13), "", IFERROR(VLOOKUP(A13, STOCKS!A:W, 15, FALSE), "")) -> -102 | P13: =IF(ISBLANK(A13), "", IFERROR(VLOOKUP(A13, STOCKS!A:W, 16, FALSE), "")) -> '----- | Q13: =IF(ISBLANK(A13), "", IFERROR(VLOOKUP(A13, STOCKS!A:W, 17, FALSE), "")) -> 0 | R13: =IF(ISBLANK(A13), "", IFERROR(VLOOKUP(A13, STOCKS!A:W, 18, FALSE), "")) -> 0 | S13: =IF(ISBLANK(A13), "", IFERROR(VLOOKUP(A13, STOCKS!A:W, 19, FALSE), "")) -> 29 | T13: =IF(ISBLANK(A13), "", IFERROR(VLOOKUP(A13, STOCKS!A:W, 20, FALSE), "")) -> 12.24 | U13: =IF(ISBLANK(A13), "", IFERROR(VLOOKUP(A13, STOCKS!A:W, 21, FALSE), "")) -> 46132 | V13: =IF(ISBLANK(A13), "", IFERROR(VLOOKUP(A13, STOCKS!A:W, 22, FALSE), ""))
A14: 1721 | B14: =IF(ISBLANK(A14), "", IFERROR(VLOOKUP(A14, STOCKS!A:W, 2, FALSE), "")) -> 三晃 | C14: =IF(ISBLANK(A14), "", IFERROR(VLOOKUP(A14, STOCKS!A:W, 3, FALSE), "")) -> 化學工業 | D14: =IF(ISBLANK(A14), "", IFERROR(VLOOKUP(A14, STOCKS!A:W, 4, FALSE), "")) -> 22.55 | E14: =IF(ISBLANK(A14), "", IFERROR(VLOOKUP(A14, STOCKS!A:W, 5, FALSE), "")) -> 2.05 | F14: =IF(ISBLANK(A14), "", IFERROR(VLOOKUP(A14, STOCKS!A:W, 6, FALSE), "")) -> 10 | G14: =IF(ISBLANK(A14), "", IFERROR(VLOOKUP(A14, STOCKS!A:W, 7, FALSE), "")) -> '+--++ | H14: =IF(ISBLANK(A14), "", IFERROR(VLOOKUP(A14, STOCKS!A:W, 8, FALSE), "")) -> 22.94 | I14: =IF(ISBLANK(A14), "", IFERROR(VLOOKUP(A14, STOCKS!A:W, 9, FALSE), "")) -> 3 | J14: =IF(ISBLANK(A14), "", IFERROR(VLOOKUP(A14, STOCKS!A:W, 10, FALSE), "")) -> 6786 | K14: =IF(ISBLANK(A14), "", IFERROR(VLOOKUP(A14, STOCKS!A:W, 11, FALSE), "")) -> 3.67 | L14: =IF(ISBLANK(A14), "", IFERROR(VLOOKUP(A14, STOCKS!A:W, 12, FALSE), "")) -> 20.2 | M14: =IF(ISBLANK(A14), "", IFERROR(VLOOKUP(A14, STOCKS!A:W, 13, FALSE), "")) -> 18.86 | N14: =IF(ISBLANK(A14), "", IFERROR(VLOOKUP(A14, STOCKS!A:W, 14, FALSE), "")) -> 18.47 | O14: =IF(ISBLANK(A14), "", IFERROR(VLOOKUP(A14, STOCKS!A:W, 15, FALSE), "")) -> 640 | P14: =IF(ISBLANK(A14), "", IFERROR(VLOOKUP(A14, STOCKS!A:W, 16, FALSE), "")) -> '++-++ | Q14: =IF(ISBLANK(A14), "", IFERROR(VLOOKUP(A14, STOCKS!A:W, 17, FALSE), "")) -> 0 | R14: =IF(ISBLANK(A14), "", IFERROR(VLOOKUP(A14, STOCKS!A:W, 18, FALSE), "")) -> 41 | S14: =IF(ISBLANK(A14), "", IFERROR(VLOOKUP(A14, STOCKS!A:W, 19, FALSE), "")) -> 0 | T14: =IF(ISBLANK(A14), "", IFERROR(VLOOKUP(A14, STOCKS!A:W, 20, FALSE), "")) -> 0 | U14: =IF(ISBLANK(A14), "", IFERROR(VLOOKUP(A14, STOCKS!A:W, 21, FALSE), "")) -> 46132 | V14: =IF(ISBLANK(A14), "", IFERROR(VLOOKUP(A14, STOCKS!A:W, 22, FALSE), ""))
A15: 6112 | B15: =IF(ISBLANK(A15), "", IFERROR(VLOOKUP(A15, STOCKS!A:W, 2, FALSE), "")) -> 邁達特 | C15: =IF(ISBLANK(A15), "", IFERROR(VLOOKUP(A15, STOCKS!A:W, 3, FALSE), "")) -> 資訊服務業 | D15: =IF(ISBLANK(A15), "", IFERROR(VLOOKUP(A15, STOCKS!A:W, 4, FALSE), "")) -> 47.9 | E15: =IF(ISBLANK(A15), "", IFERROR(VLOOKUP(A15, STOCKS!A:W, 5, FALSE), "")) -> -0.15 | F15: =IF(ISBLANK(A15), "", IFERROR(VLOOKUP(A15, STOCKS!A:W, 6, FALSE), "")) -> -0.31 | G15: =IF(ISBLANK(A15), "", IFERROR(VLOOKUP(A15, STOCKS!A:W, 7, FALSE), "")) -> '++++- | H15: =IF(ISBLANK(A15), "", IFERROR(VLOOKUP(A15, STOCKS!A:W, 8, FALSE), "")) -> 3.86 | I15: =IF(ISBLANK(A15), "", IFERROR(VLOOKUP(A15, STOCKS!A:W, 9, FALSE), "")) -> 0 | J15: =IF(ISBLANK(A15), "", IFERROR(VLOOKUP(A15, STOCKS!A:W, 10, FALSE), "")) -> 548 | K15: =IF(ISBLANK(A15), "", IFERROR(VLOOKUP(A15, STOCKS!A:W, 11, FALSE), "")) -> 0.29 | L15: =IF(ISBLANK(A15), "", IFERROR(VLOOKUP(A15, STOCKS!A:W, 12, FALSE), "")) -> 47.47 | M15: =IF(ISBLANK(A15), "", IFERROR(VLOOKUP(A15, STOCKS!A:W, 13, FALSE), "")) -> 46.89 | N15: =IF(ISBLANK(A15), "", IFERROR(VLOOKUP(A15, STOCKS!A:W, 14, FALSE), "")) -> 45.67 | O15: =IF(ISBLANK(A15), "", IFERROR(VLOOKUP(A15, STOCKS!A:W, 15, FALSE), "")) -> 78 | P15: =IF(ISBLANK(A15), "", IFERROR(VLOOKUP(A15, STOCKS!A:W, 16, FALSE), "")) -> '+++++ | Q15: =IF(ISBLANK(A15), "", IFERROR(VLOOKUP(A15, STOCKS!A:W, 17, FALSE), "")) -> 0 | R15: =IF(ISBLANK(A15), "", IFERROR(VLOOKUP(A15, STOCKS!A:W, 18, FALSE), "")) -> -8 | S15: =IF(ISBLANK(A15), "", IFERROR(VLOOKUP(A15, STOCKS!A:W, 19, FALSE), "")) -> 126 | T15: =IF(ISBLANK(A15), "", IFERROR(VLOOKUP(A15, STOCKS!A:W, 20, FALSE), "")) -> 22.99 | U15: =IF(ISBLANK(A15), "", IFERROR(VLOOKUP(A15, STOCKS!A:W, 21, FALSE), "")) -> 46132 | V15: =IF(ISBLANK(A15), "", IFERROR(VLOOKUP(A15, STOCKS!A:W, 22, FALSE), ""))
... A29: 2344 | B29: =IF(ISBLANK(A29), "", IFERROR(VLOOKUP(A29, STOCKS!A:W, 2, FALSE), "")) -> 華邦電 | C29: =IF(ISBLANK(A29), "", IFERROR(VLOOKUP(A29, STOCKS!A:W, 3, FALSE), "")) -> 半導體業 | D29: =IF(ISBLANK(A29), "", IFERROR(VLOOKUP(A29, STOCKS!A:W, 4, FALSE), "")) -> 85.7 | E29: =IF(ISBLANK(A29), "", IFERROR(VLOOKUP(A29, STOCKS!A:W, 5, FALSE), "")) -> -2.1 | F29: =IF(ISBLANK(A29), "", IFERROR(VLOOKUP(A29, STOCKS!A:W, 6, FALSE), "")) -> -2.39 | G29: =IF(ISBLANK(A29), "", IFERROR(VLOOKUP(A29, STOCKS!A:W, 7, FALSE), "")) -> '----- | H29: =IF(ISBLANK(A29), "", IFERROR(VLOOKUP(A29, STOCKS!A:W, 8, FALSE), "")) -> -9.55 | I29: =IF(ISBLANK(A29), "", IFERROR(VLOOKUP(A29, STOCKS!A:W, 9, FALSE), "")) -> 0 | J29: =IF(ISBLANK(A29), "", IFERROR(VLOOKUP(A29, STOCKS!A:W, 10, FALSE), "")) -> 164660 | K29: =IF(ISBLANK(A29), "", IFERROR(VLOOKUP(A29, STOCKS!A:W, 11, FALSE), "")) -> 3.66 | L29: =IF(ISBLANK(A29), "", IFERROR(VLOOKUP(A29, STOCKS!A:W, 12, FALSE), "")) -> 89.36 | M29: =IF(ISBLANK(A29), "", IFERROR(VLOOKUP(A29, STOCKS!A:W, 13, FALSE), "")) -> 91.07 | N29: =IF(ISBLANK(A29), "", IFERROR(VLOOKUP(A29, STOCKS!A:W, 14, FALSE), "")) -> 94.12 | O29: =IF(ISBLANK(A29), "", IFERROR(VLOOKUP(A29, STOCKS!A:W, 15, FALSE), "")) -> 49497 | P29: =IF(ISBLANK(A29), "", IFERROR(VLOOKUP(A29, STOCKS!A:W, 16, FALSE), "")) -> '--+++ | Q29: =IF(ISBLANK(A29), "", IFERROR(VLOOKUP(A29, STOCKS!A:W, 17, FALSE), "")) -> -7986 | R29: =IF(ISBLANK(A29), "", IFERROR(VLOOKUP(A29, STOCKS!A:W, 18, FALSE), "")) -> 1331 | S29: =IF(ISBLANK(A29), "", IFERROR(VLOOKUP(A29, STOCKS!A:W, 19, FALSE), "")) -> 60976 | T29: =IF(ISBLANK(A29), "", IFERROR(VLOOKUP(A29, STOCKS!A:W, 20, FALSE), "")) -> 37.03 | U29: =IF(ISBLANK(A29), "", IFERROR(VLOOKUP(A29, STOCKS!A:W, 21, FALSE), "")) -> 46132 | V29: =IF(ISBLANK(A29), "", IFERROR(VLOOKUP(A29, STOCKS!A:W, 22, FALSE), ""))

Sheet 紅綠-題材股
C1: 選股符合打V | E1: 參考 | H1: V | J1: 參考 | K1: V | L1: V | M1: 參考 | O1: 參考 | Q1: V | T1: 參考
C2: 條件: | E2: <150 | H2: 為 - - | J2: >=3 | K2: >2000 | L2: >5 | M2: MA5逼近MA10 | O2: D<N | Q2: 為 + + | T2: >成交*50% | W2: https://mops.twse.com.tw/mops/#/web/home
A3: ID | B3: Name | C3: Type | D3: 題材類型 | E3: 收盤價 | F3: 價差 | G3: 漲幅(%) | H3: 五日+- | I3: 五日漲幅 (%) | J3: 漲停歷史 | K3: 交易量 (張) | L3: 周轉率 (%) | M3: MA5 | N3: MA10 | O3: MA20 | P3: 外資 (張) | Q3: 外資 五日+- | R3: 投信 (張) | S3: 自營 (張) | T3: 當沖 (張) | U3: 當沖 (%) | V3: Date | W3: 第 1 欄 | X3: 第 2 欄 | Y3: 第 3 欄 | Z3: 第 4 欄 | AA3: 第 26 欄
A4: 題材-軍工
A5: 2634 | B5: =IF(ISBLANK(A5), "", IFERROR(VLOOKUP(A5, STOCKS!A:W, 2, FALSE), "")) -> 漢翔 | C5: =IF(ISBLANK(A5), "", IFERROR(VLOOKUP(A5, STOCKS!A:W, 3, FALSE), "")) -> 航運業 | D5: =IF(ISBLANK(A5), "", IFERROR(VLOOKUP(A5, category!A:C, 3, FALSE), "")) -> 軍工/航太 | E5: =IF(ISBLANK(A5), "", IFERROR(VLOOKUP(A5, STOCKS!A:W, 4, FALSE), "")) -> 50.4 | F5: =IF(ISBLANK(A5), "", IFERROR(VLOOKUP(A5, STOCKS!A:W, 5, FALSE), "")) -> 0 | G5: =IF(ISBLANK(A5), "", IFERROR(VLOOKUP(A5, STOCKS!A:W, 6, FALSE), "")) -> 0 | H5: =IF(ISBLANK(A5), "", IFERROR(VLOOKUP(A5, STOCKS!A:W, 7, FALSE), "")) -> '++++- | I5: =IF(ISBLANK(A5), "", IFERROR(VLOOKUP(A5, STOCKS!A:W, 8, FALSE), "")) -> 7.19 | J5: =IF(ISBLANK(A5), "", IFERROR(VLOOKUP(A5, STOCKS!A:W, 9, FALSE), "")) -> 0 | K5: =IF(ISBLANK(A5), "", IFERROR(VLOOKUP(A5, STOCKS!A:W, 10, FALSE), "")) -> 6483 | L5: =IF(ISBLANK(A5), "", IFERROR(VLOOKUP(A5, STOCKS!A:W, 11, FALSE), "")) -> 0.69 | M5: =IF(ISBLANK(A5), "", IFERROR(VLOOKUP(A5, STOCKS!A:W, 12, FALSE), "")) -> 49.14 | N5: =IF(ISBLANK(A5), "", IFERROR(VLOOKUP(A5, STOCKS!A:W, 13, FALSE), "")) -> 47.93 | O5: =IF(ISBLANK(A5), "", IFERROR(VLOOKUP(A5, STOCKS!A:W, 14, FALSE), "")) -> 48.3 | P5: =IF(ISBLANK(A5), "", IFERROR(VLOOKUP(A5, STOCKS!A:W, 15, FALSE), "")) -> -799 | Q5: =IF(ISBLANK(A5), "", IFERROR(VLOOKUP(A5, STOCKS!A:W, 16, FALSE), "")) -> '+-++- | R5: =IF(ISBLANK(A5), "", IFERROR(VLOOKUP(A5, STOCKS!A:W, 17, FALSE), "")) -> -6 | S5: =IF(ISBLANK(A5), "", IFERROR(VLOOKUP(A5, STOCKS!A:W, 18, FALSE), "")) -> 4 | T5: =IF(ISBLANK(A5), "", IFERROR(VLOOKUP(A5, STOCKS!A:W, 19, FALSE), "")) -> 1976 | U5: =IF(ISBLANK(A5), "", IFERROR(VLOOKUP(A5, STOCKS!A:W, 20, FALSE), "")) -> 30.48 | V5: =IF(ISBLANK(A5), "", IFERROR(VLOOKUP(A5, STOCKS!A:W, 21, FALSE), "")) -> 46132 | W5: =IF(ISBLANK(A5), "", IFERROR(VLOOKUP(A5, STOCKS!A:W, 22, FALSE), ""))
A6: 2645 | B6: =IF(ISBLANK(A6), "", IFERROR(VLOOKUP(A6, STOCKS!A:W, 2, FALSE), "")) -> 長榮航太 | C6: =IF(ISBLANK(A6), "", IFERROR(VLOOKUP(A6, STOCKS!A:W, 3, FALSE), "")) -> 航運業 | D6: =IF(ISBLANK(A6), "", IFERROR(VLOOKUP(A6, category!A:C, 3, FALSE), "")) -> 軍工/航太 | E6: =IF(ISBLANK(A6), "", IFERROR(VLOOKUP(A6, STOCKS!A:W, 4, FALSE), "")) -> 166 | F6: =IF(ISBLANK(A6), "", IFERROR(VLOOKUP(A6, STOCKS!A:W, 5, FALSE), "")) -> 5.5 | G6: =IF(ISBLANK(A6), "", IFERROR(VLOOKUP(A6, STOCKS!A:W, 6, FALSE), "")) -> 3.43 | H6: =IF(ISBLANK(A6), "", IFERROR(VLOOKUP(A6, STOCKS!A:W, 7, FALSE), "")) -> '+++++ | I6: =IF(ISBLANK(A6), "", IFERROR(VLOOKUP(A6, STOCKS!A:W, 8, FALSE), "")) -> 9.93 | J6: =IF(ISBLANK(A6), "", IFERROR(VLOOKUP(A6, STOCKS!A:W, 9, FALSE), "")) -> 0 | K6: =IF(ISBLANK(A6), "", IFERROR(VLOOKUP(A6, STOCKS!A:W, 10, FALSE), "")) -> 2331 | L6: =IF(ISBLANK(A6), "", IFERROR(VLOOKUP(A6, STOCKS!A:W, 11, FALSE), "")) -> 0.62 | M6: =IF(ISBLANK(A6), "", IFERROR(VLOOKUP(A6, STOCKS!A:W, 12, FALSE), "")) -> 157.6 | N6: =IF(ISBLANK(A6), "", IFERROR(VLOOKUP(A6, STOCKS!A:W, 13, FALSE), "")) -> 153.55 | O6: =IF(ISBLANK(A6), "", IFERROR(VLOOKUP(A6, STOCKS!A:W, 14, FALSE), "")) -> 151.78 | P6: =IF(ISBLANK(A6), "", IFERROR(VLOOKUP(A6, STOCKS!A:W, 15, FALSE), "")) -> 893 | Q6: =IF(ISBLANK(A6), "", IFERROR(VLOOKUP(A6, STOCKS!A:W, 16, FALSE), "")) -> '+++++ | R6: =IF(ISBLANK(A6), "", IFERROR(VLOOKUP(A6, STOCKS!A:W, 17, FALSE), "")) -> -3 | S6: =IF(ISBLANK(A6), "", IFERROR(VLOOKUP(A6, STOCKS!A:W, 18, FALSE), "")) -> 74 | T6: =IF(ISBLANK(A6), "", IFERROR(VLOOKUP(A6, STOCKS!A:W, 19, FALSE), "")) -> 656 | U6: =IF(ISBLANK(A6), "", IFERROR(VLOOKUP(A6, STOCKS!A:W, 20, FALSE), "")) -> 28.14 | V6: =IF(ISBLANK(A6), "", IFERROR(VLOOKUP(A6, STOCKS!A:W, 21, FALSE), "")) -> 46132 | W6: =IF(ISBLANK(A6), "", IFERROR(VLOOKUP(A6, STOCKS!A:W, 22, FALSE), ""))
A7: 4541 | B7: =IF(ISBLANK(A7), "", IFERROR(VLOOKUP(A7, STOCKS!A:W, 2, FALSE), "")) -> 晟田 | C7: =IF(ISBLANK(A7), "", IFERROR(VLOOKUP(A7, STOCKS!A:W, 3, FALSE), "")) -> 其他業 | D7: =IF(ISBLANK(A7), "", IFERROR(VLOOKUP(A7, category!A:C, 3, FALSE), "")) -> 軍工/航太 | E7: =IF(ISBLANK(A7), "", IFERROR(VLOOKUP(A7, STOCKS!A:W, 4, FALSE), "")) -> 49.35 | F7: =IF(ISBLANK(A7), "", IFERROR(VLOOKUP(A7, STOCKS!A:W, 5, FALSE), "")) -> 1.05 | G7: =IF(ISBLANK(A7), "", IFERROR(VLOOKUP(A7, STOCKS!A:W, 6, FALSE), "")) -> 2.17 | H7: =IF(ISBLANK(A7), "", IFERROR(VLOOKUP(A7, STOCKS!A:W, 7, FALSE), "")) -> '+-+++ | I7: =IF(ISBLANK(A7), "", IFERROR(VLOOKUP(A7, STOCKS!A:W, 8, FALSE), "")) -> 6.37 | J7: =IF(ISBLANK(A7), "", IFERROR(VLOOKUP(A7, STOCKS!A:W, 9, FALSE), "")) -> 1 | K7: =IF(ISBLANK(A7), "", IFERROR(VLOOKUP(A7, STOCKS!A:W, 10, FALSE), "")) -> 3379 | L7: =IF(ISBLANK(A7), "", IFERROR(VLOOKUP(A7, STOCKS!A:W, 11, FALSE), "")) -> 5 | M7: =IF(ISBLANK(A7), "", IFERROR(VLOOKUP(A7, STOCKS!A:W, 12, FALSE), "")) -> 47.72 | N7: =IF(ISBLANK(A7), "", IFERROR(VLOOKUP(A7, STOCKS!A:W, 13, FALSE), "")) -> 45.71 | O7: =IF(ISBLANK(A7), "", IFERROR(VLOOKUP(A7, STOCKS!A:W, 14, FALSE), "")) -> 43.71 | P7: =IF(ISBLANK(A7), "", IFERROR(VLOOKUP(A7, STOCKS!A:W, 15, FALSE), "")) -> 438 | Q7: =IF(ISBLANK(A7), "", IFERROR(VLOOKUP(A7, STOCKS!A:W, 16, FALSE), "")) -> '+++++ | R7: =IF(ISBLANK(A7), "", IFERROR(VLOOKUP(A7, STOCKS!A:W, 17, FALSE), "")) -> 0 | S7: =IF(ISBLANK(A7), "", IFERROR(VLOOKUP(A7, STOCKS!A:W, 18, FALSE), "")) -> 2 | T7: =IF(ISBLANK(A7), "", IFERROR(VLOOKUP(A7, STOCKS!A:W, 19, FALSE), "")) -> 1176 | U7: =IF(ISBLANK(A7), "", IFERROR(VLOOKUP(A7, STOCKS!A:W, 20, FALSE), "")) -> 34.8 | V7: =IF(ISBLANK(A7), "", IFERROR(VLOOKUP(A7, STOCKS!A:W, 21, FALSE), "")) -> 46132 | W7: =IF(ISBLANK(A7), "", IFERROR(VLOOKUP(A7, STOCKS!A:W, 22, FALSE), ""))
A8: 4572 | B8: =IF(ISBLANK(A8), "", IFERROR(VLOOKUP(A8, STOCKS!A:W, 2, FALSE), "")) -> 駐龍 | C8: =IF(ISBLANK(A8), "", IFERROR(VLOOKUP(A8, STOCKS!A:W, 3, FALSE), "")) -> 電機機械 | D8: =IF(ISBLANK(A8), "", IFERROR(VLOOKUP(A8, category!A:C, 3, FALSE), "")) -> 軍工/航太 | E8: =IF(ISBLANK(A8), "", IFERROR(VLOOKUP(A8, STOCKS!A:W, 4, FALSE), "")) -> 148 | F8: =IF(ISBLANK(A8), "", IFERROR(VLOOKUP(A8, STOCKS!A:W, 5, FALSE), "")) -> 1.5 | G8: =IF(ISBLANK(A8), "", IFERROR(VLOOKUP(A8, STOCKS!A:W, 6, FALSE), "")) -> 1.02 | H8: =IF(ISBLANK(A8), "", IFERROR(VLOOKUP(A8, STOCKS!A:W, 7, FALSE), "")) -> '+++++ | I8: =IF(ISBLANK(A8), "", IFERROR(VLOOKUP(A8, STOCKS!A:W, 8, FALSE), "")) -> 4.51 | J8: =IF(ISBLANK(A8), "", IFERROR(VLOOKUP(A8, STOCKS!A:W, 9, FALSE), "")) -> 0 | K8: =IF(ISBLANK(A8), "", IFERROR(VLOOKUP(A8, STOCKS!A:W, 10, FALSE), "")) -> 49 | L8: =IF(ISBLANK(A8), "", IFERROR(VLOOKUP(A8, STOCKS!A:W, 11, FALSE), "")) -> 0.12 | M8: =IF(ISBLANK(A8), "", IFERROR(VLOOKUP(A8, STOCKS!A:W, 12, FALSE), "")) -> 145.6 | N8: =IF(ISBLANK(A8), "", IFERROR(VLOOKUP(A8, STOCKS!A:W, 13, FALSE), "")) -> 143.55 | O8: =IF(ISBLANK(A8), "", IFERROR(VLOOKUP(A8, STOCKS!A:W, 14, FALSE), "")) -> 143 | P8: =IF(ISBLANK(A8), "", IFERROR(VLOOKUP(A8, STOCKS!A:W, 15, FALSE), "")) -> 20 | Q8: =IF(ISBLANK(A8), "", IFERROR(VLOOKUP(A8, STOCKS!A:W, 16, FALSE), "")) -> '+++++ | R8: =IF(ISBLANK(A8), "", IFERROR(VLOOKUP(A8, STOCKS!A:W, 17, FALSE), "")) -> 0 | S8: =IF(ISBLANK(A8), "", IFERROR(VLOOKUP(A8, STOCKS!A:W, 18, FALSE), "")) -> 0 | T8: =IF(ISBLANK(A8), "", IFERROR(VLOOKUP(A8, STOCKS!A:W, 19, FALSE), "")) -> 11 | U8: =IF(ISBLANK(A8), "", IFERROR(VLOOKUP(A8, STOCKS!A:W, 20, FALSE), "")) -> 22.45 | V8: =IF(ISBLANK(A8), "", IFERROR(VLOOKUP(A8, STOCKS!A:W, 21, FALSE), "")) -> 46132 | W8: =IF(ISBLANK(A8), "", IFERROR(VLOOKUP(A8, STOCKS!A:W, 22, FALSE), ""))
